Workbook

Sheet カテゴリ
A1: 名前 | B1: 切断補正 | C1: 貫通補正 | D1: 打撃補正 | E1: 速度ペナルティ | F1: 種別 | G1: 使用例
A2: 鉱石 | B2: 25 | C2: 25 | D2: 15 | E2: -20 | F2: 鉄鉱石、銀鉱石、魔石 | G2: 武器や防具の基本素材。
A3: 鱗 | B3: 15 | C3: 15 | D3: 15 | E3: -15 | F3: ドラゴンの鱗、水生生物の鱗 | G3: 重装防具、耐久性の高い防具。
A4: 木材 | B4: 5 | C4: 15 | D4: 10 | E4: -10 | F4: アイアンウッド、フレイムウッド | G4: 棒系武器、弓、軽量武器の素材。
A5: 骨 | B5: 10 | C5: 0 | D5: 5 | E5: -5 | F5: 魔獣の骨、大型獣の牙 | G5: 軽量武器、特殊防具、装飾品。
A6: 皮 | B6: 5 | C6: 5 | D6: 5 | E6: -5 | F6: 普通の皮、硬革、魔獣の皮 | G6: 軽装防具、グリップ、補強材。
A7: 布 | B7: 0 | C7: 0 | D7: 0 | E7: 0 | F7: 普通の布、魔法織布 | G7: 軽装防具、バッグ、補助アイテム。
A8: 糸 | F8: 魔力繊維、蜘蛛の糸 | G8: 弦、軽装防具、魔法アイテム。
A9: 宝石 | F9: 魔石、エメラルド | G9: 属性付与、魔法強化、特殊装備。
A10: 液体 | F10: 魔獣の血、特殊な溶液 | G10: ポーション、魔法武器、属性強化。
A11: 特殊 | F11: 星鉄、隕石の欠片 | G11: レア武器や防具、特別な効果の付与。

Sheet 装備品
A1: 名前 | B1: ルビ | C1: 分類 | D1: 素材 | E1: 種別 | F1: 全力 | G1: 切断 | H1: 貫通 | I1: 打撃 | J1: ガード | K1: 射撃 | L1: 属性 | M1: 属性値 | N1: 変動 | O1: Cr率 | P1: Cr威力 | Q1: 回避率 | R1: 命中率 | S1: 射程 | T1: 弾倉 | U1: リロード時間 | V1: 攻撃回数 | W1: 攻撃タイプ | X1: 能力 | Y1: 武器特性 | Z1: 物理軽減 | AA1: 魔法軽減 | AB1: 切断耐性 | AC1: 貫通耐性 | AD1: 打撃耐性 | AE1: 炎耐性 | AF1: 氷耐性 | AG1: 雷耐性 | AH1: 酸耐性 | AI1: 音耐性 | AJ1: 闇耐性 | AK1: 光耐性 | AL1: 善耐性 | AM1: 悪耐性 | AN1: 正耐性 | AO1: 精神耐性 | AP1: 毒耐性 | AQ1: 盲目耐性 | AR1: 幻覚耐性 | AS1: 石化耐性 | AT1: 怯み耐性 | AU1: 拘束耐性 | AV1: 呪い耐性 | AW1: 即死耐性 | AX1: 時間耐性 | AY1: 出血耐性 | AZ1: 疲労耐性 | BA1: 体幹耐性 | BB1: 物理耐性 | BC1: 魔法耐性 | BD1: Cr率耐性 | BE1: Cr威力耐性 | BF1: Lv | BG1: HP | BH1: MP | BI1: ST | BJ1: 攻撃 | BK1: 防御 | BL1: 魔力 | BM1: 精神 | BN1: 速度 | BO1: 命中 | BP1: SIZ | BQ1: APP | BR1: 隠密 | BS1: 感知 | BT1: 威圧 | BU1: 軽業 | BV1: 技術 | BW1: 早業 | BX1: 看破 | BY1: 騙す | BZ1: 知識 | CA1: 鑑定 | CB1: 装置 | CC1: 変装 | CD1: 制作 | CE1: 精神接続 | CF1: 魔法技術 | CG1: 指揮 | CH1: 重量 | CI1: 付与 | CJ1: 能力 | CK1: 能力2 | CL1: 威力 | CM1: 画像url | CN1: 金額 | CO1: 素材の説明 | CP1: 武器の説明 | CQ1: 説明 | CR1: id | CS1: 元金額
A2: - | B2: - | C2: - | D2: - | E2: - | F2: - | G2: - | H2: - | I2: - | J2: - | K2: - | L2: - | M2: - | N2: ダメージの振れ幅 | O2: - | P2: - | Q2: - | R2: - | S2: - | T2: - | U2: - | V2: - | W2: - | X2: - | Y2: - | Z2: - | CR2: ="e_"&ROW(CR2) -> e_2
A3: =D3&"の"&C3 -> 鉄の短刀 | B3: =IFERROR(VLOOKUP($D3,素材!$1:$1016,COLUMN($B$1),FALSE)&"・"&VLOOKUP($C3,武器!$1:$998,COLUMN(B$1),FALSE),"") -> アイアン・ナイフ | C3: 短刀 | D3: 鉄 | E3: =IFERROR(VLOOKUP(C3,武器!$1:$998,COLUMN(C$1),FALSE),"") -> 武器 | F3: =IFERROR(ROUNDDOWN((VLOOKUP($C3,武器!$1:$998,COLUMN(D$1),FALSE)+IFERROR(VLOOKUP($CI3,装強!$1:$999,COLUMN(F$1),FALSE),0))*VLOOKUP($D3,素材!$1:$1016,COLUMN(D$1),FALSE),0),"") -> 100 | G3: =IFERROR(ROUNDDOWN((VLOOKUP($C3,武器!$1:$998,COLUMN(E$1),FALSE)+IFERROR(VLOOKUP($CI3,装強!$1:$999,COLUMN(G$1),FALSE),0))*VLOOKUP($D3,素材!$1:$1016,COLUMN($E$1),FALSE),0),"") -> 10 | H3: =IFERROR(ROUNDDOWN((VLOOKUP($C3,武器!$1:$998,COLUMN(F$1),FALSE)+IFERROR(VLOOKUP($CI3,装強!$1:$999,COLUMN(H$1),FALSE),0))*VLOOKUP($D3,素材!$1:$1016,COLUMN($E$1),FALSE),0),"") -> 8 | I3: =IFERROR(ROUNDDOWN((VLOOKUP($C3,武器!$1:$998,COLUMN(G$1),FALSE)+IFERROR(VLOOKUP($CI3,装強!$1:$999,COLUMN(I$1),FALSE),0))*VLOOKUP($D3,素材!$1:$1016,COLUMN($E$1),FALSE),0),"") -> 2 | J3: =IFERROR(ROUNDDOWN((VLOOKUP($C3,武器!$1:$998,COLUMN(H$1),FALSE)+IFERROR(VLOOKUP($CI3,装強!$1:$999,COLUMN(J$1),FALSE),0))*VLOOKUP($D3,素材!$1:$1016,COLUMN($E$1),FALSE),0),"") -> 13 | K3: =IFERROR(ROUNDDOWN((VLOOKUP($C3,武器!$1:$998,COLUMN(I$1),FALSE)+IFERROR(VLOOKUP($CI3,装強!$1:$999,COLUMN(K$1),FALSE),0))*VLOOKUP($D3,素材!$1:$1016,COLUMN($E$1),FALSE),0),"") -> 0 | L3: =IFERROR(VLOOKUP($D3,素材!$1:$1016,COLUMN($F$1),FALSE),"") -> 0 | M3: =IFERROR(VLOOKUP($C3,武器!$1:$998,COLUMN(AA$1),FALSE)*VLOOKUP($D3,素材!$1:$1016,COLUMN($G$1),FALSE),"") -> 0 | N3: =IFERROR(VLOOKUP($C3,武器!$1:$998,COLUMN(I$1),FALSE),"") -> 0 | O3: =IFERROR((VLOOKUP($C3,武器!$1:$998,COLUMN(K$1),FALSE)+VLOOKUP($D3,素材!$1:$1016,COLUMN(H$1),FALSE))*100+IFERROR(VLOOKUP($CI3,装強!$1:$999,COLUMN(O$1),FALSE),0),"") -> 10 | P3: =IFERROR((VLOOKUP($C3,武器!$1:$998,COLUMN(L$1),FALSE)+VLOOKUP($D3,素材!$1:$1016,COLUMN(I$1),FALSE))*100+IFERROR(VLOOKUP($CI3,装強!$1:$999,COLUMN(P$1),FALSE),0),"") -> 175 | Q3: =IFERROR(ROUNDUP(VLOOKUP($C3,武器!$1:$998,COLUMN(M$1),FALSE)*(VLOOKUP($D3,素材!$1:$1002,COLUMN(D$1),FALSE)/100),1),"") -> 0 | R3: =IFERROR(ROUNDUP(VLOOKUP($C3,武器!$1:$998,COLUMN(N$1),FALSE)*(VLOOKUP($D3,素材!$1:$1002,COLUMN(D$1),FALSE)/100),1),"") -> 0 | S3: =IFERROR(VLOOKUP($C3,武器!$1:$998,COLUMN(P$1),FALSE),"") -> 0 | T3: =IFERROR(VLOOKUP($C3,武器!$1:$998,COLUMN(Q$1),FALSE),"") -> 0 | U3: =IFERROR(VLOOKUP($C3,武器!$1:$998,COLUMN(R$1),FALSE),"") -> 0 | V3: =IFERROR(VLOOKUP($C3,武器!$1:$998,COLUMN(Q$1),FALSE),"") -> 0 | W3: =IFERROR(VLOOKUP($C3,武器!$1:$998,COLUMN(T$1),FALSE),"") -> A | Y3: =IFERROR(VLOOKUP($C3,武器!$1:$998,COLUMN(U$1),FALSE),"") -> 暗殺強化,片手適正Ⅱ | Z3: =IFERROR(ROUNDUP(VLOOKUP($C3,武器!$1:$998,COLUMN(O$1),FALSE)*VLOOKUP($D3,素材!$1:$1016,COLUMN(E$1),FALSE),1),"") -> 0 | AA3: =IF(ISNUMBER(SEARCH(SUBSTITUTE(AA$1,RIGHT(AA$1,2),""),VLOOKUP($D3,素材!$1:$1016,COLUMN($F$1),FALSE))),VLOOKUP($C3,武器!$1:$998,COLUMN($O$1),FALSE)*VLOOKUP($D3,素材!$1:$1016,COLUMN($E$1),FALSE)/(LEN(VLOOKUP($D3,素材!$1:$1016,COLUMN($F$1),FALSE)) - LEN(SUBSTITUTE(VLOOKUP($D3,素材!$1:$1016,COLUMN($F$1),FALSE), "・", 0)) + 1), 0) -> 0 | AB3: =IF(ISNUMBER(SEARCH(SUBSTITUTE(AB$1,RIGHT(AB$1,2),""),VLOOKUP($D3,素材!$1:$1016,COLUMN($F$1),FALSE))),VLOOKUP($C3,武器!$1:$998,COLUMN($O$1),FALSE)*VLOOKUP($D3,素材!$1:$1016,COLUMN($E$1),FALSE)/(LEN(VLOOKUP($D3,素材!$1:$1016,COLUMN($F$1),FALSE)) - LEN(SUBSTITUTE(VLOOKUP($D3,素材!$1:$1016,COLUMN($F$1),FALSE), "・", 0)) + 1), 0) -> 0 | AC3: =IF(ISNUMBER(SEARCH(SUBSTITUTE(AC$1,RIGHT(AC$1,2),""),VLOOKUP($D3,素材!$1:$1016,COLUMN($F$1),FALSE))),VLOOKUP($C3,武器!$1:$998,COLUMN($O$1),FALSE)*VLOOKUP($D3,素材!$1:$1016,COLUMN($E$1),FALSE)/(LEN(VLOOKUP($D3,素材!$1:$1016,COLUMN($F$1),FALSE)) - LEN(SUBSTITUTE(VLOOKUP($D3,素材!$1:$1016,COLUMN($F$1),FALSE), "・", 0)) + 1), 0) -> 0 | AD3: =IF(ISNUMBER(SEARCH(SUBSTITUTE(AD$1,RIGHT(AD$1,2),""),VLOOKUP($D3,素材!$1:$1016,COLUMN($F$1),FALSE))),VLOOKUP($C3,武器!$1:$998,COLUMN($O$1),FALSE)*VLOOKUP($D3,素材!$1:$1016,COLUMN($E$1),FALSE)/(LEN(VLOOKUP($D3,素材!$1:$1016,COLUMN($F$1),FALSE)) - LEN(SUBSTITUTE(VLOOKUP($D3,素材!$1:$1016,COLUMN($F$1),FALSE), "・", 0)) + 1), 0) -> 0 | AE3: =IF(ISNUMBER(SEARCH(SUBSTITUTE(AE$1,RIGHT(AE$1,2),""),VLOOKUP($D3,素材!$1:$1016,COLUMN($F$1),FALSE))),VLOOKUP($C3,武器!$1:$998,COLUMN($O$1),FALSE)*VLOOKUP($D3,素材!$1:$1016,COLUMN($E$1),FALSE)/(LEN(VLOOKUP($D3,素材!$1:$1016,COLUMN($F$1),FALSE)) - LEN(SUBSTITUTE(VLOOKUP($D3,素材!$1:$1016,COLUMN($F$1),FALSE), "・", 0)) + 1), 0) -> 0 | AF3: =IF(ISNUMBER(SEARCH(SUBSTITUTE(AF$1,RIGHT(AF$1,2),""),VLOOKUP($D3,素材!$1:$1016,COLUMN($F$1),FALSE))),VLOOKUP($C3,武器!$1:$998,COLUMN($O$1),FALSE)*VLOOKUP($D3,素材!$1:$1016,COLUMN($E$1),FALSE)/(LEN(VLOOKUP($D3,素材!$1:$1016,COLUMN($F$1),FALSE)) - LEN(SUBSTITUTE(VLOOKUP($D3,素材!$1:$1016,COLUMN($F$1),FALSE), "・", 0)) + 1), 0) -> 0 | AG3: =IF(ISNUMBER(SEARCH(SUBSTITUTE(AG$1,RIGHT(AG$1,2),""),VLOOKUP($D3,素材!$1:$1016,COLUMN($F$1),FALSE))),VLOOKUP($C3,武器!$1:$998,COLUMN($O$1),FALSE)*VLOOKUP($D3,素材!$1:$1016,COLUMN($E$1),FALSE)/(LEN(VLOOKUP($D3,素材!$1:$1016,COLUMN($F$1),FALSE)) - LEN(SUBSTITUTE(VLOOKUP($D3,素材!$1:$1016,COLUMN($F$1),FALSE), "・", 0)) + 1), 0) -> 0 | AH3: =IF(ISNUMBER(SEARCH(SUBSTITUTE(AH$1,RIGHT(AH$1,2),""),VLOOKUP($D3,素材!$1:$1016,COLUMN($F$1),FALSE))),VLOOKUP($C3,武器!$1:$998,COLUMN($O$1),FALSE)*VLOOKUP($D3,素材!$1:$1016,COLUMN($E$1),FALSE)/(LEN(VLOOKUP($D3,素材!$1:$1016,COLUMN($F$1),FALSE)) - LEN(SUBSTITUTE(VLOOKUP($D3,素材!$1:$1016,COLUMN($F$1),FALSE), "・", 0)) + 1), 0) -> 0 | ... BE3: =IF(ISNUMBER(SEARCH(SUBSTITUTE(BE$1,RIGHT(BE$1,2),""),VLOOKUP($D3,素材!$1:$1016,COLUMN($F$1),FALSE))),VLOOKUP($C3,武器!$1:$998,COLUMN($O$1),FALSE)*VLOOKUP($D3,素材!$1:$1016,COLUMN($E$1),FALSE)/(LEN(VLOOKUP($D3,素材!$1:$1016,COLUMN($F$1),FALSE)) - LEN(SUBSTITUTE(VLOOKUP($D3,素材!$1:$1016,COLUMN($F$1),FALSE), "・", 0)) + 1), 0) -> 0 | CL3: =SUM(G3:I3) -> 20 | CM3: =IF(E3="武器",IF(J3-1>SUM(G3:I3),"盾",IF(MAX(G3:I3)=G3,"切断",IF(MAX(G3:I3)=H3,"貫通",IF(MAX(G3:I3)=I3,"打撃","射撃")))),E3)&".webp" -> 切断.webp | CN3: =IFERROR(VLOOKUP($C3,武器!$1:$998,COLUMN(V$1),FALSE)*VLOOKUP($D3,素材!$1:$1016,COLUMN(N$1),FALSE)+IF(CI3="",0,VLOOKUP($CI3,装強!$1:$1008,COLUMN($CK$1),FALSE)),"") -> 200 | CO3: =VLOOKUP(D3,素材!$A:$O,COLUMN(素材!O$1),FALSE) -> 一般的な鉄。量産品を作るのに使用されることが多い | CP3: =VLOOKUP(C3,武器!$A:$W,COLUMN(武器!W$1),FALSE) -> 短刀。暗殺向けの武器で、軽量かつ片手操作に適する。Cr威力が高い | CR3: ="e_"&ROW(CR3) -> e_3 | CS3: =CN3*100 -> 20000
A4: =D4&"の"&C4 -> 鉄の刀 | B4: =IFERROR(VLOOKUP($D4,素材!$1:$1016,COLUMN($B$1),FALSE)&"・"&VLOOKUP($C4,武器!$1:$998,COLUMN(B$1),FALSE),"") -> アイアン・カタナ | C4: 刀 | D4: 鉄 | E4: =IFERROR(VLOOKUP(C4,武器!$1:$998,COLUMN(C$1),FALSE),"") -> 武器 | F4: =IFERROR(ROUNDDOWN((VLOOKUP($C4,武器!$1:$998,COLUMN(D$1),FALSE)+IFERROR(VLOOKUP($CI4,装強!$1:$999,COLUMN(F$1),FALSE),0))*VLOOKUP($D4,素材!$1:$1016,COLUMN(D$1),FALSE),0),"") -> 105 | G4: =IFERROR(ROUNDDOWN((VLOOKUP($C4,武器!$1:$998,COLUMN(E$1),FALSE)+IFERROR(VLOOKUP($CI4,装強!$1:$999,COLUMN(G$1),FALSE),0))*VLOOKUP($D4,素材!$1:$1016,COLUMN($E$1),FALSE),0),"") -> 14 | H4: =IFERROR(ROUNDDOWN((VLOOKUP($C4,武器!$1:$998,COLUMN(F$1),FALSE)+IFERROR(VLOOKUP($CI4,装強!$1:$999,COLUMN(H$1),FALSE),0))*VLOOKUP($D4,素材!$1:$1016,COLUMN($E$1),FALSE),0),"") -> 8 | I4: =IFERROR(ROUNDDOWN((VLOOKUP($C4,武器!$1:$998,COLUMN(G$1),FALSE)+IFERROR(VLOOKUP($CI4,装強!$1:$999,COLUMN(I$1),FALSE),0))*VLOOKUP($D4,素材!$1:$1016,COLUMN($E$1),FALSE),0),"") -> 2 | J4: =IFERROR(ROUNDDOWN((VLOOKUP($C4,武器!$1:$998,COLUMN(H$1),FALSE)+IFERROR(VLOOKUP($CI4,装強!$1:$999,COLUMN(J$1),FALSE),0))*VLOOKUP($D4,素材!$1:$1016,COLUMN($E$1),FALSE),0),"") -> 17 | K4: =IFERROR(ROUNDDOWN((VLOOKUP($C4,武器!$1:$998,COLUMN(I$1),FALSE)+IFERROR(VLOOKUP($CI4,装強!$1:$999,COLUMN(K$1),FALSE),0))*VLOOKUP($D4,素材!$1:$1016,COLUMN($E$1),FALSE),0),"") -> 0 | L4: =IFERROR(VLOOKUP($D4,素材!$1:$1016,COLUMN($F$1),FALSE),"") -> 0 | M4: =IFERROR(VLOOKUP($C4,武器!$1:$998,COLUMN(AA$1),FALSE)*VLOOKUP($D4,素材!$1:$1016,COLUMN($G$1),FALSE),"") -> 0 | N4: =IFERROR(VLOOKUP($C4,武器!$1:$998,COLUMN(I$1),FALSE),"") -> 0 | O4: =IFERROR((VLOOKUP($C4,武器!$1:$998,COLUMN(K$1),FALSE)+VLOOKUP($D4,素材!$1:$1016,COLUMN(H$1),FALSE))*100+IFERROR(VLOOKUP($CI4,装強!$1:$999,COLUMN(O$1),FALSE),0),"") -> 10 | P4: =IFERROR((VLOOKUP($C4,武器!$1:$998,COLUMN(L$1),FALSE)+VLOOKUP($D4,素材!$1:$1016,COLUMN(I$1),FALSE))*100+IFERROR(VLOOKUP($CI4,装強!$1:$999,COLUMN(P$1),FALSE),0),"") -> 175 | Q4: =IFERROR(ROUNDUP(VLOOKUP($C4,武器!$1:$998,COLUMN(M$1),FALSE)*(VLOOKUP($D4,素材!$1:$1002,COLUMN(D$1),FALSE)/100),1),"") -> 0 | R4: =IFERROR(ROUNDUP(VLOOKUP($C4,武器!$1:$998,COLUMN(N$1),FALSE)*(VLOOKUP($D4,素材!$1:$1002,COLUMN(D$1),FALSE)/100),1),"") -> 0 | S4: =IFERROR(VLOOKUP($C4,武器!$1:$998,COLUMN(P$1),FALSE),"") -> 0 | T4: =IFERROR(VLOOKUP($C4,武器!$1:$998,COLUMN(Q$1),FALSE),"") -> 0 | U4: =IFERROR(VLOOKUP($C4,武器!$1:$998,COLUMN(R$1),FALSE),"") -> 0 | V4: =IFERROR(VLOOKUP($C4,武器!$1:$998,COLUMN(Q$1),FALSE),"") -> 0 | W4: =IFERROR(VLOOKUP($C4,武器!$1:$998,COLUMN(T$1),FALSE),"") -> A | Y4: =IFERROR(VLOOKUP($C4,武器!$1:$998,COLUMN(U$1),FALSE),"") -> 0 | Z4: =IFERROR(ROUNDUP(VLOOKUP($C4,武器!$1:$998,COLUMN(O$1),FALSE)*VLOOKUP($D4,素材!$1:$1016,COLUMN(E$1),FALSE),1),"") -> 0 | AA4: =IF(ISNUMBER(SEARCH(SUBSTITUTE(AA$1,RIGHT(AA$1,2),""),VLOOKUP($D4,素材!$1:$1016,COLUMN($F$1),FALSE))),VLOOKUP($C4,武器!$1:$998,COLUMN($O$1),FALSE)*VLOOKUP($D4,素材!$1:$1016,COLUMN($E$1),FALSE)/(LEN(VLOOKUP($D4,素材!$1:$1016,COLUMN($F$1),FALSE)) - LEN(SUBSTITUTE(VLOOKUP($D4,素材!$1:$1016,COLUMN($F$1),FALSE), "・", 0)) + 1), 0) -> 0 | AB4: =IF(ISNUMBER(SEARCH(SUBSTITUTE(AB$1,RIGHT(AB$1,2),""),VLOOKUP($D4,素材!$1:$1016,COLUMN($F$1),FALSE))),VLOOKUP($C4,武器!$1:$998,COLUMN($O$1),FALSE)*VLOOKUP($D4,素材!$1:$1016,COLUMN($E$1),FALSE)/(LEN(VLOOKUP($D4,素材!$1:$1016,COLUMN($F$1),FALSE)) - LEN(SUBSTITUTE(VLOOKUP($D4,素材!$1:$1016,COLUMN($F$1),FALSE), "・", 0)) + 1), 0) -> 0 | AC4: =IF(ISNUMBER(SEARCH(SUBSTITUTE(AC$1,RIGHT(AC$1,2),""),VLOOKUP($D4,素材!$1:$1016,COLUMN($F$1),FALSE))),VLOOKUP($C4,武器!$1:$998,COLUMN($O$1),FALSE)*VLOOKUP($D4,素材!$1:$1016,COLUMN($E$1),FALSE)/(LEN(VLOOKUP($D4,素材!$1:$1016,COLUMN($F$1),FALSE)) - LEN(SUBSTITUTE(VLOOKUP($D4,素材!$1:$1016,COLUMN($F$1),FALSE), "・", 0)) + 1), 0) -> 0 | AD4: =IF(ISNUMBER(SEARCH(SUBSTITUTE(AD$1,RIGHT(AD$1,2),""),VLOOKUP($D4,素材!$1:$1016,COLUMN($F$1),FALSE))),VLOOKUP($C4,武器!$1:$998,COLUMN($O$1),FALSE)*VLOOKUP($D4,素材!$1:$1016,COLUMN($E$1),FALSE)/(LEN(VLOOKUP($D4,素材!$1:$1016,COLUMN($F$1),FALSE)) - LEN(SUBSTITUTE(VLOOKUP($D4,素材!$1:$1016,COLUMN($F$1),FALSE), "・", 0)) + 1), 0) -> 0 | AE4: =IF(ISNUMBER(SEARCH(SUBSTITUTE(AE$1,RIGHT(AE$1,2),""),VLOOKUP($D4,素材!$1:$1016,COLUMN($F$1),FALSE))),VLOOKUP($C4,武器!$1:$998,COLUMN($O$1),FALSE)*VLOOKUP($D4,素材!$1:$1016,COLUMN($E$1),FALSE)/(LEN(VLOOKUP($D4,素材!$1:$1016,COLUMN($F$1),FALSE)) - LEN(SUBSTITUTE(VLOOKUP($D4,素材!$1:$1016,COLUMN($F$1),FALSE), "・", 0)) + 1), 0) -> 0 | AF4: =IF(ISNUMBER(SEARCH(SUBSTITUTE(AF$1,RIGHT(AF$1,2),""),VLOOKUP($D4,素材!$1:$1016,COLUMN($F$1),FALSE))),VLOOKUP($C4,武器!$1:$998,COLUMN($O$1),FALSE)*VLOOKUP($D4,素材!$1:$1016,COLUMN($E$1),FALSE)/(LEN(VLOOKUP($D4,素材!$1:$1016,COLUMN($F$1),FALSE)) - LEN(SUBSTITUTE(VLOOKUP($D4,素材!$1:$1016,COLUMN($F$1),FALSE), "・", 0)) + 1), 0) -> 0 | AG4: =IF(ISNUMBER(SEARCH(SUBSTITUTE(AG$1,RIGHT(AG$1,2),""),VLOOKUP($D4,素材!$1:$1016,COLUMN($F$1),FALSE))),VLOOKUP($C4,武器!$1:$998,COLUMN($O$1),FALSE)*VLOOKUP($D4,素材!$1:$1016,COLUMN($E$1),FALSE)/(LEN(VLOOKUP($D4,素材!$1:$1016,COLUMN($F$1),FALSE)) - LEN(SUBSTITUTE(VLOOKUP($D4,素材!$1:$1016,COLUMN($F$1),FALSE), "・", 0)) + 1), 0) -> 0 | AH4: =IF(ISNUMBER(SEARCH(SUBSTITUTE(AH$1,RIGHT(AH$1,2),""),VLOOKUP($D4,素材!$1:$1016,COLUMN($F$1),FALSE))),VLOOKUP($C4,武器!$1:$998,COLUMN($O$1),FALSE)*VLOOKUP($D4,素材!$1:$1016,COLUMN($E$1),FALSE)/(LEN(VLOOKUP($D4,素材!$1:$1016,COLUMN($F$1),FALSE)) - LEN(SUBSTITUTE(VLOOKUP($D4,素材!$1:$1016,COLUMN($F$1),FALSE), "・", 0)) + 1), 0) -> 0 | ... BE4: =IF(ISNUMBER(SEARCH(SUBSTITUTE(BE$1,RIGHT(BE$1,2),""),VLOOKUP($D4,素材!$1:$1016,COLUMN($F$1),FALSE))),VLOOKUP($C4,武器!$1:$998,COLUMN($O$1),FALSE)*VLOOKUP($D4,素材!$1:$1016,COLUMN($E$1),FALSE)/(LEN(VLOOKUP($D4,素材!$1:$1016,COLUMN($F$1),FALSE)) - LEN(SUBSTITUTE(VLOOKUP($D4,素材!$1:$1016,COLUMN($F$1),FALSE), "・", 0)) + 1), 0) -> 0 | CL4: =SUM(G4:I4) -> 24 | CM4: =IF(E4="武器",IF(J4-1>SUM(G4:I4),"盾",IF(MAX(G4:I4)=G4,"切断",IF(MAX(G4:I4)=H4,"貫通",IF(MAX(G4:I4)=I4,"打撃","射撃")))),E4)&".webp" -> 切断.webp | CN4: =IFERROR(VLOOKUP($C4,武器!$1:$998,COLUMN(V$1),FALSE)*VLOOKUP($D4,素材!$1:$1016,COLUMN(N$1),FALSE)+IF(CI4="",0,VLOOKUP($CI4,装強!$1:$1008,COLUMN($CK$1),FALSE)),"") -> 400 | CO4: =VLOOKUP(D4,素材!$A:$O,COLUMN(素材!O$1),FALSE) -> 一般的な鉄。量産品を作るのに使用されることが多い | CP4: =VLOOKUP(C4,武器!$A:$W,COLUMN(武器!W$1),FALSE) -> 刀。切断力に優れた武器で、Cr威力が高い | CR4: ="e_"&ROW(CR4) -> e_4 | CS4: =CN4*100 -> 40000
A5: =D5&"の"&C5 -> 鉄の剣 | B5: =IFERROR(VLOOKUP($D5,素材!$1:$1016,COLUMN($B$1),FALSE)&"・"&VLOOKUP($C5,武器!$1:$998,COLUMN(B$1),FALSE),"") -> アイアン・ソード | C5: 剣 | D5: 鉄 | E5: =IFERROR(VLOOKUP(C5,武器!$1:$998,COLUMN(C$1),FALSE),"") -> 武器 | F5: =IFERROR(ROUNDDOWN((VLOOKUP($C5,武器!$1:$998,COLUMN(D$1),FALSE)+IFERROR(VLOOKUP($CI5,装強!$1:$999,COLUMN(F$1),FALSE),0))*VLOOKUP($D5,素材!$1:$1016,COLUMN(D$1),FALSE),0),"") -> 100 | G5: =IFERROR(ROUNDDOWN((VLOOKUP($C5,武器!$1:$998,COLUMN(E$1),FALSE)+IFERROR(VLOOKUP($CI5,装強!$1:$999,COLUMN(G$1),FALSE),0))*VLOOKUP($D5,素材!$1:$1016,COLUMN($E$1),FALSE),0),"") -> 12 | H5: =IFERROR(ROUNDDOWN((VLOOKUP($C5,武器!$1:$998,COLUMN(F$1),FALSE)+IFERROR(VLOOKUP($CI5,装強!$1:$999,COLUMN(H$1),FALSE),0))*VLOOKUP($D5,素材!$1:$1016,COLUMN($E$1),FALSE),0),"") -> 9 | I5: =IFERROR(ROUNDDOWN((VLOOKUP($C5,武器!$1:$998,COLUMN(G$1),FALSE)+IFERROR(VLOOKUP($CI5,装強!$1:$999,COLUMN(I$1),FALSE),0))*VLOOKUP($D5,素材!$1:$1016,COLUMN($E$1),FALSE),0),"") -> 3 | J5: =IFERROR(ROUNDDOWN((VLOOKUP($C5,武器!$1:$998,COLUMN(H$1),FALSE)+IFERROR(VLOOKUP($CI5,装強!$1:$999,COLUMN(J$1),FALSE),0))*VLOOKUP($D5,素材!$1:$1016,COLUMN($E$1),FALSE),0),"") -> 19 | K5: =IFERROR(ROUNDDOWN((VLOOKUP($C5,武器!$1:$998,COLUMN(I$1),FALSE)+IFERROR(VLOOKUP($CI5,装強!$1:$999,COLUMN(K$1),FALSE),0))*VLOOKUP($D5,素材!$1:$1016,COLUMN($E$1),FALSE),0),"") -> 0 | L5: =IFERROR(VLOOKUP($D5,素材!$1:$1016,COLUMN($F$1),FALSE),"") -> 0 | M5: =IFERROR(VLOOKUP($C5,武器!$1:$998,COLUMN(AA$1),FALSE)*VLOOKUP($D5,素材!$1:$1016,COLUMN($G$1),FALSE),"") -> 0 | N5: =IFERROR(VLOOKUP($C5,武器!$1:$998,COLUMN(I$1),FALSE),"") -> 0 | O5: =IFERROR((VLOOKUP($C5,武器!$1:$998,COLUMN(K$1),FALSE)+VLOOKUP($D5,素材!$1:$1016,COLUMN(H$1),FALSE))*100+IFERROR(VLOOKUP($CI5,装強!$1:$999,COLUMN(O$1),FALSE),0),"") -> 10 | P5: =IFERROR((VLOOKUP($C5,武器!$1:$998,COLUMN(L$1),FALSE)+VLOOKUP($D5,素材!$1:$1016,COLUMN(I$1),FALSE))*100+IFERROR(VLOOKUP($CI5,装強!$1:$999,COLUMN(P$1),FALSE),0),"") -> 150 | Q5: =IFERROR(ROUNDUP(VLOOKUP($C5,武器!$1:$998,COLUMN(M$1),FALSE)*(VLOOKUP($D5,素材!$1:$1002,COLUMN(D$1),FALSE)/100),1),"") -> 0 | R5: =IFERROR(ROUNDUP(VLOOKUP($C5,武器!$1:$998,COLUMN(N$1),FALSE)*(VLOOKUP($D5,素材!$1:$1002,COLUMN(D$1),FALSE)/100),1),"") -> 0 | S5: =IFERROR(VLOOKUP($C5,武器!$1:$998,COLUMN(P$1),FALSE),"") -> 0 | T5: =IFERROR(VLOOKUP($C5,武器!$1:$998,COLUMN(Q$1),FALSE),"") -> 0 | U5: =IFERROR(VLOOKUP($C5,武器!$1:$998,COLUMN(R$1),FALSE),"") -> 0 | V5: =IFERROR(VLOOKUP($C5,武器!$1:$998,COLUMN(Q$1),FALSE),"") -> 0 | W5: =IFERROR(VLOOKUP($C5,武器!$1:$998,COLUMN(T$1),FALSE),"") -> A | Y5: =IFERROR(VLOOKUP($C5,武器!$1:$998,COLUMN(U$1),FALSE),"") -> 片手適正Ⅰ | Z5: =IFERROR(ROUNDUP(VLOOKUP($C5,武器!$1:$998,COLUMN(O$1),FALSE)*VLOOKUP($D5,素材!$1:$1016,COLUMN(E$1),FALSE),1),"") -> 0 | AA5: =IF(ISNUMBER(SEARCH(SUBSTITUTE(AA$1,RIGHT(AA$1,2),""),VLOOKUP($D5,素材!$1:$1016,COLUMN($F$1),FALSE))),VLOOKUP($C5,武器!$1:$998,COLUMN($O$1),FALSE)*VLOOKUP($D5,素材!$1:$1016,COLUMN($E$1),FALSE)/(LEN(VLOOKUP($D5,素材!$1:$1016,COLUMN($F$1),FALSE)) - LEN(SUBSTITUTE(VLOOKUP($D5,素材!$1:$1016,COLUMN($F$1),FALSE), "・", 0)) + 1), 0) -> 0 | AB5: =IF(ISNUMBER(SEARCH(SUBSTITUTE(AB$1,RIGHT(AB$1,2),""),VLOOKUP($D5,素材!$1:$1016,COLUMN($F$1),FALSE))),VLOOKUP($C5,武器!$1:$998,COLUMN($O$1),FALSE)*VLOOKUP($D5,素材!$1:$1016,COLUMN($E$1),FALSE)/(LEN(VLOOKUP($D5,素材!$1:$1016,COLUMN($F$1),FALSE)) - LEN(SUBSTITUTE(VLOOKUP($D5,素材!$1:$1016,COLUMN($F$1),FALSE), "・", 0)) + 1), 0) -> 0 | AC5: =IF(ISNUMBER(SEARCH(SUBSTITUTE(AC$1,RIGHT(AC$1,2),""),VLOOKUP($D5,素材!$1:$1016,COLUMN($F$1),FALSE))),VLOOKUP($C5,武器!$1:$998,COLUMN($O$1),FALSE)*VLOOKUP($D5,素材!$1:$1016,COLUMN($E$1),FALSE)/(LEN(VLOOKUP($D5,素材!$1:$1016,COLUMN($F$1),FALSE)) - LEN(SUBSTITUTE(VLOOKUP($D5,素材!$1:$1016,COLUMN($F$1),FALSE), "・", 0)) + 1), 0) -> 0 | AD5: =IF(ISNUMBER(SEARCH(SUBSTITUTE(AD$1,RIGHT(AD$1,2),""),VLOOKUP($D5,素材!$1:$1016,COLUMN($F$1),FALSE))),VLOOKUP($C5,武器!$1:$998,COLUMN($O$1),FALSE)*VLOOKUP($D5,素材!$1:$1016,COLUMN($E$1),FALSE)/(LEN(VLOOKUP($D5,素材!$1:$1016,COLUMN($F$1),FALSE)) - LEN(SUBSTITUTE(VLOOKUP($D5,素材!$1:$1016,COLUMN($F$1),FALSE), "・", 0)) + 1), 0) -> 0 | AE5: =IF(ISNUMBER(SEARCH(SUBSTITUTE(AE$1,RIGHT(AE$1,2),""),VLOOKUP($D5,素材!$1:$1016,COLUMN($F$1),FALSE))),VLOOKUP($C5,武器!$1:$998,COLUMN($O$1),FALSE)*VLOOKUP($D5,素材!$1:$1016,COLUMN($E$1),FALSE)/(LEN(VLOOKUP($D5,素材!$1:$1016,COLUMN($F$1),FALSE)) - LEN(SUBSTITUTE(VLOOKUP($D5,素材!$1:$1016,COLUMN($F$1),FALSE), "・", 0)) + 1), 0) -> 0 | AF5: =IF(ISNUMBER(SEARCH(SUBSTITUTE(AF$1,RIGHT(AF$1,2),""),VLOOKUP($D5,素材!$1:$1016,COLUMN($F$1),FALSE))),VLOOKUP($C5,武器!$1:$998,COLUMN($O$1),FALSE)*VLOOKUP($D5,素材!$1:$1016,COLUMN($E$1),FALSE)/(LEN(VLOOKUP($D5,素材!$1:$1016,COLUMN($F$1),FALSE)) - LEN(SUBSTITUTE(VLOOKUP($D5,素材!$1:$1016,COLUMN($F$1),FALSE), "・", 0)) + 1), 0) -> 0 | AG5: =IF(ISNUMBER(SEARCH(SUBSTITUTE(AG$1,RIGHT(AG$1,2),""),VLOOKUP($D5,素材!$1:$1016,COLUMN($F$1),FALSE))),VLOOKUP($C5,武器!$1:$998,COLUMN($O$1),FALSE)*VLOOKUP($D5,素材!$1:$1016,COLUMN($E$1),FALSE)/(LEN(VLOOKUP($D5,素材!$1:$1016,COLUMN($F$1),FALSE)) - LEN(SUBSTITUTE(VLOOKUP($D5,素材!$1:$1016,COLUMN($F$1),FALSE), "・", 0)) + 1), 0) -> 0 | AH5: =IF(ISNUMBER(SEARCH(SUBSTITUTE(AH$1,RIGHT(AH$1,2),""),VLOOKUP($D5,素材!$1:$1016,COLUMN($F$1),FALSE))),VLOOKUP($C5,武器!$1:$998,COLUMN($O$1),FALSE)*VLOOKUP($D5,素材!$1:$1016,COLUMN($E$1),FALSE)/(LEN(VLOOKUP($D5,素材!$1:$1016,COLUMN($F$1),FALSE)) - LEN(SUBSTITUTE(VLOOKUP($D5,素材!$1:$1016,COLUMN($F$1),FALSE), "・", 0)) + 1), 0) -> 0 | ... BE5: =IF(ISNUMBER(SEARCH(SUBSTITUTE(BE$1,RIGHT(BE$1,2),""),VLOOKUP($D5,素材!$1:$1016,COLUMN($F$1),FALSE))),VLOOKUP($C5,武器!$1:$998,COLUMN($O$1),FALSE)*VLOOKUP($D5,素材!$1:$1016,COLUMN($E$1),FALSE)/(LEN(VLOOKUP($D5,素材!$1:$1016,COLUMN($F$1),FALSE)) - LEN(SUBSTITUTE(VLOOKUP($D5,素材!$1:$1016,COLUMN($F$1),FALSE), "・", 0)) + 1), 0) -> 0 | CL5: =SUM(G5:I5) -> 24 | CM5: =IF(E5="武器",IF(J5-1>SUM(G5:I5),"盾",IF(MAX(G5:I5)=G5,"切断",IF(MAX(G5:I5)=H5,"貫通",IF(MAX(G5:I5)=I5,"打撃","射撃")))),E5)&".webp" -> 切断.webp | CN5: =IFERROR(VLOOKUP($C5,武器!$1:$998,COLUMN(V$1),FALSE)*VLOOKUP($D5,素材!$1:$1016,COLUMN(N$1),FALSE)+IF(CI5="",0,VLOOKUP($CI5,装強!$1:$1008,COLUMN($CK$1),FALSE)),"") -> 300 | CO5: =VLOOKUP(D5,素材!$A:$O,COLUMN(素材!O$1),FALSE) -> 一般的な鉄。量産品を作るのに使用されることが多い | CP5: =VLOOKUP(C5,武器!$A:$W,COLUMN(武器!W$1),FALSE) -> 剣。短い剣で片手で扱いやすく、初心者向けの武器。 | CR5: ="e_"&ROW(CR5) -> e_5 | CS5: =CN5*100 -> 30000
A6: =D6&"の"&C6 -> 鉄の広剣 | B6: =IFERROR(VLOOKUP($D6,素材!$1:$1016,COLUMN($B$1),FALSE)&"・"&VLOOKUP($C6,武器!$1:$998,COLUMN(B$1),FALSE),"") -> アイアン・ブロードソード | C6: 広剣 | D6: 鉄 | E6: =IFERROR(VLOOKUP(C6,武器!$1:$998,COLUMN(C$1),FALSE),"") -> 武器 | F6: =IFERROR(ROUNDDOWN((VLOOKUP($C6,武器!$1:$998,COLUMN(D$1),FALSE)+IFERROR(VLOOKUP($CI6,装強!$1:$999,COLUMN(F$1),FALSE),0))*VLOOKUP($D6,素材!$1:$1016,COLUMN(D$1),FALSE),0),"") -> 110 | G6: =IFERROR(ROUNDDOWN((VLOOKUP($C6,武器!$1:$998,COLUMN(E$1),FALSE)+IFERROR(VLOOKUP($CI6,装強!$1:$999,COLUMN(G$1),FALSE),0))*VLOOKUP($D6,素材!$1:$1016,COLUMN($E$1),FALSE),0),"") -> 12 | H6: =IFERROR(ROUNDDOWN((VLOOKUP($C6,武器!$1:$998,COLUMN(F$1),FALSE)+IFERROR(VLOOKUP($CI6,装強!$1:$999,COLUMN(H$1),FALSE),0))*VLOOKUP($D6,素材!$1:$1016,COLUMN($E$1),FALSE),0),"") -> 8 | I6: =IFERROR(ROUNDDOWN((VLOOKUP($C6,武器!$1:$998,COLUMN(G$1),FALSE)+IFERROR(VLOOKUP($CI6,装強!$1:$999,COLUMN(I$1),FALSE),0))*VLOOKUP($D6,素材!$1:$1016,COLUMN($E$1),FALSE),0),"") -> 3 | J6: =IFERROR(ROUNDDOWN((VLOOKUP($C6,武器!$1:$998,COLUMN(H$1),FALSE)+IFERROR(VLOOKUP($CI6,装強!$1:$999,COLUMN(J$1),FALSE),0))*VLOOKUP($D6,素材!$1:$1016,COLUMN($E$1),FALSE),0),"") -> 23 | K6: =IFERROR(ROUNDDOWN((VLOOKUP($C6,武器!$1:$998,COLUMN(I$1),FALSE)+IFERROR(VLOOKUP($CI6,装強!$1:$999,COLUMN(K$1),FALSE),0))*VLOOKUP($D6,素材!$1:$1016,COLUMN($E$1),FALSE),0),"") -> 0 | L6: =IFERROR(VLOOKUP($D6,素材!$1:$1016,COLUMN($F$1),FALSE),"") -> 0 | M6: =IFERROR(VLOOKUP($C6,武器!$1:$998,COLUMN(AA$1),FALSE)*VLOOKUP($D6,素材!$1:$1016,COLUMN($G$1),FALSE),"") -> 0 | N6: =IFERROR(VLOOKUP($C6,武器!$1:$998,COLUMN(I$1),FALSE),"") -> 0 | O6: =IFERROR((VLOOKUP($C6,武器!$1:$998,COLUMN(K$1),FALSE)+VLOOKUP($D6,素材!$1:$1016,COLUMN(H$1),FALSE))*100+IFERROR(VLOOKUP($CI6,装強!$1:$999,COLUMN(O$1),FALSE),0),"") -> 10 | P6: =IFERROR((VLOOKUP($C6,武器!$1:$998,COLUMN(L$1),FALSE)+VLOOKUP($D6,素材!$1:$1016,COLUMN(I$1),FALSE))*100+IFERROR(VLOOKUP($CI6,装強!$1:$999,COLUMN(P$1),FALSE),0),"") -> 150 | Q6: =IFERROR(ROUNDUP(VLOOKUP($C6,武器!$1:$998,COLUMN(M$1),FALSE)*(VLOOKUP($D6,素材!$1:$1002,COLUMN(D$1),FALSE)/100),1),"") -> -2.5 | R6: =IFERROR(ROUNDUP(VLOOKUP($C6,武器!$1:$998,COLUMN(N$1),FALSE)*(VLOOKUP($D6,素材!$1:$1002,COLUMN(D$1),FALSE)/100),1),"") -> -2.5 | S6: =IFERROR(VLOOKUP($C6,武器!$1:$998,COLUMN(P$1),FALSE),"") -> 0 | T6: =IFERROR(VLOOKUP($C6,武器!$1:$998,COLUMN(Q$1),FALSE),"") -> 0 | U6: =IFERROR(VLOOKUP($C6,武器!$1:$998,COLUMN(R$1),FALSE),"") -> 0 | V6: =IFERROR(VLOOKUP($C6,武器!$1:$998,COLUMN(Q$1),FALSE),"") -> 0 | W6: =IFERROR(VLOOKUP($C6,武器!$1:$998,COLUMN(T$1),FALSE),"") -> A | Y6: =IFERROR(VLOOKUP($C6,武器!$1:$998,COLUMN(U$1),FALSE),"") -> 0 | Z6: =IFERROR(ROUNDUP(VLOOKUP($C6,武器!$1:$998,COLUMN(O$1),FALSE)*VLOOKUP($D6,素材!$1:$1016,COLUMN(E$1),FALSE),1),"") -> 0 | AA6: =IF(ISNUMBER(SEARCH(SUBSTITUTE(AA$1,RIGHT(AA$1,2),""),VLOOKUP($D6,素材!$1:$1016,COLUMN($F$1),FALSE))),VLOOKUP($C6,武器!$1:$998,COLUMN($O$1),FALSE)*VLOOKUP($D6,素材!$1:$1016,COLUMN($E$1),FALSE)/(LEN(VLOOKUP($D6,素材!$1:$1016,COLUMN($F$1),FALSE)) - LEN(SUBSTITUTE(VLOOKUP($D6,素材!$1:$1016,COLUMN($F$1),FALSE), "・", 0)) + 1), 0) -> 0 | AB6: =IF(ISNUMBER(SEARCH(SUBSTITUTE(AB$1,RIGHT(AB$1,2),""),VLOOKUP($D6,素材!$1:$1016,COLUMN($F$1),FALSE))),VLOOKUP($C6,武器!$1:$998,COLUMN($O$1),FALSE)*VLOOKUP($D6,素材!$1:$1016,COLUMN($E$1),FALSE)/(LEN(VLOOKUP($D6,素材!$1:$1016,COLUMN($F$1),FALSE)) - LEN(SUBSTITUTE(VLOOKUP($D6,素材!$1:$1016,COLUMN($F$1),FALSE), "・", 0)) + 1), 0) -> 0 | AC6: =IF(ISNUMBER(SEARCH(SUBSTITUTE(AC$1,RIGHT(AC$1,2),""),VLOOKUP($D6,素材!$1:$1016,COLUMN($F$1),FALSE))),VLOOKUP($C6,武器!$1:$998,COLUMN($O$1),FALSE)*VLOOKUP($D6,素材!$1:$1016,COLUMN($E$1),FALSE)/(LEN(VLOOKUP($D6,素材!$1:$1016,COLUMN($F$1),FALSE)) - LEN(SUBSTITUTE(VLOOKUP($D6,素材!$1:$1016,COLUMN($F$1),FALSE), "・", 0)) + 1), 0) -> 0 | AD6: =IF(ISNUMBER(SEARCH(SUBSTITUTE(AD$1,RIGHT(AD$1,2),""),VLOOKUP($D6,素材!$1:$1016,COLUMN($F$1),FALSE))),VLOOKUP($C6,武器!$1:$998,COLUMN($O$1),FALSE)*VLOOKUP($D6,素材!$1:$1016,COLUMN($E$1),FALSE)/(LEN(VLOOKUP($D6,素材!$1:$1016,COLUMN($F$1),FALSE)) - LEN(SUBSTITUTE(VLOOKUP($D6,素材!$1:$1016,COLUMN($F$1),FALSE), "・", 0)) + 1), 0) -> 0 | AE6: =IF(ISNUMBER(SEARCH(SUBSTITUTE(AE$1,RIGHT(AE$1,2),""),VLOOKUP($D6,素材!$1:$1016,COLUMN($F$1),FALSE))),VLOOKUP($C6,武器!$1:$998,COLUMN($O$1),FALSE)*VLOOKUP($D6,素材!$1:$1016,COLUMN($E$1),FALSE)/(LEN(VLOOKUP($D6,素材!$1:$1016,COLUMN($F$1),FALSE)) - LEN(SUBSTITUTE(VLOOKUP($D6,素材!$1:$1016,COLUMN($F$1),FALSE), "・", 0)) + 1), 0) -> 0 | AF6: =IF(ISNUMBER(SEARCH(SUBSTITUTE(AF$1,RIGHT(AF$1,2),""),VLOOKUP($D6,素材!$1:$1016,COLUMN($F$1),FALSE))),VLOOKUP($C6,武器!$1:$998,COLUMN($O$1),FALSE)*VLOOKUP($D6,素材!$1:$1016,COLUMN($E$1),FALSE)/(LEN(VLOOKUP($D6,素材!$1:$1016,COLUMN($F$1),FALSE)) - LEN(SUBSTITUTE(VLOOKUP($D6,素材!$1:$1016,COLUMN($F$1),FALSE), "・", 0)) + 1), 0) -> 0 | AG6: =IF(ISNUMBER(SEARCH(SUBSTITUTE(AG$1,RIGHT(AG$1,2),""),VLOOKUP($D6,素材!$1:$1016,COLUMN($F$1),FALSE))),VLOOKUP($C6,武器!$1:$998,COLUMN($O$1),FALSE)*VLOOKUP($D6,素材!$1:$1016,COLUMN($E$1),FALSE)/(LEN(VLOOKUP($D6,素材!$1:$1016,COLUMN($F$1),FALSE)) - LEN(SUBSTITUTE(VLOOKUP($D6,素材!$1:$1016,COLUMN($F$1),FALSE), "・", 0)) + 1), 0) -> 0 | AH6: =IF(ISNUMBER(SEARCH(SUBSTITUTE(AH$1,RIGHT(AH$1,2),""),VLOOKUP($D6,素材!$1:$1016,COLUMN($F$1),FALSE))),VLOOKUP($C6,武器!$1:$998,COLUMN($O$1),FALSE)*VLOOKUP($D6,素材!$1:$1016,COLUMN($E$1),FALSE)/(LEN(VLOOKUP($D6,素材!$1:$1016,COLUMN($F$1),FALSE)) - LEN(SUBSTITUTE(VLOOKUP($D6,素材!$1:$1016,COLUMN($F$1),FALSE), "・", 0)) + 1), 0) -> 0 | ... BE6: =IF(ISNUMBER(SEARCH(SUBSTITUTE(BE$1,RIGHT(BE$1,2),""),VLOOKUP($D6,素材!$1:$1016,COLUMN($F$1),FALSE))),VLOOKUP($C6,武器!$1:$998,COLUMN($O$1),FALSE)*VLOOKUP($D6,素材!$1:$1016,COLUMN($E$1),FALSE)/(LEN(VLOOKUP($D6,素材!$1:$1016,COLUMN($F$1),FALSE)) - LEN(SUBSTITUTE(VLOOKUP($D6,素材!$1:$1016,COLUMN($F$1),FALSE), "・", 0)) + 1), 0) -> 0 | CL6: =SUM(G6:I6) -> 23 | CM6: =IF(E6="武器",IF(J6-1>SUM(G6:I6),"盾",IF(MAX(G6:I6)=G6,"切断",IF(MAX(G6:I6)=H6,"貫通",IF(MAX(G6:I6)=I6,"打撃","射撃")))),E6)&".webp" -> 切断.webp | CN6: =IFERROR(VLOOKUP($C6,武器!$1:$998,COLUMN(V$1),FALSE)*VLOOKUP($D6,素材!$1:$1016,COLUMN(N$1),FALSE)+IF(CI6="",0,VLOOKUP($CI6,装強!$1:$1008,COLUMN($CK$1),FALSE)),"") -> 400 | CO6: =VLOOKUP(D6,素材!$A:$O,COLUMN(素材!O$1),FALSE) -> 一般的な鉄。量産品を作るのに使用されることが多い | CP6: =VLOOKUP(C6,武器!$A:$W,COLUMN(武器!W$1),FALSE) -> 幅の広い剣。扱いにくいが攻撃と防御にも優れている。状況に合わせて立ち回ろう。 | CR6: ="e_"&ROW(CR6) -> e_6 | CS6: =CN6*100 -> 40000
A7: =D7&"の"&C7 -> 鉄の長剣 | B7: =IFERROR(VLOOKUP($D7,素材!$1:$1016,COLUMN($B$1),FALSE)&"・"&VLOOKUP($C7,武器!$1:$998,COLUMN(B$1),FALSE),"") -> アイアン・ロングソード | C7: 長剣 | D7: 鉄 | E7: =IFERROR(VLOOKUP(C7,武器!$1:$998,COLUMN(C$1),FALSE),"") -> 武器 | F7: =IFERROR(ROUNDDOWN((VLOOKUP($C7,武器!$1:$998,COLUMN(D$1),FALSE)+IFERROR(VLOOKUP($CI7,装強!$1:$999,COLUMN(F$1),FALSE),0))*VLOOKUP($D7,素材!$1:$1016,COLUMN(D$1),FALSE),0),"") -> 115 | G7: =IFERROR(ROUNDDOWN((VLOOKUP($C7,武器!$1:$998,COLUMN(E$1),FALSE)+IFERROR(VLOOKUP($CI7,装強!$1:$999,COLUMN(G$1),FALSE),0))*VLOOKUP($D7,素材!$1:$1016,COLUMN($E$1),FALSE),0),"") -> 15 | H7: =IFERROR(ROUNDDOWN((VLOOKUP($C7,武器!$1:$998,COLUMN(F$1),FALSE)+IFERROR(VLOOKUP($CI7,装強!$1:$999,COLUMN(H$1),FALSE),0))*VLOOKUP($D7,素材!$1:$1016,COLUMN($E$1),FALSE),0),"") -> 9 | I7: =IFERROR(ROUNDDOWN((VLOOKUP($C7,武器!$1:$998,COLUMN(G$1),FALSE)+IFERROR(VLOOKUP($CI7,装強!$1:$999,COLUMN(I$1),FALSE),0))*VLOOKUP($D7,素材!$1:$1016,COLUMN($E$1),FALSE),0),"") -> 3 | J7: =IFERROR(ROUNDDOWN((VLOOKUP($C7,武器!$1:$998,COLUMN(H$1),FALSE)+IFERROR(VLOOKUP($CI7,装強!$1:$999,COLUMN(J$1),FALSE),0))*VLOOKUP($D7,素材!$1:$1016,COLUMN($E$1),FALSE),0),"") -> 20 | K7: =IFERROR(ROUNDDOWN((VLOOKUP($C7,武器!$1:$998,COLUMN(I$1),FALSE)+IFERROR(VLOOKUP($CI7,装強!$1:$999,COLUMN(K$1),FALSE),0))*VLOOKUP($D7,素材!$1:$1016,COLUMN($E$1),FALSE),0),"") -> 0 | L7: =IFERROR(VLOOKUP($D7,素材!$1:$1016,COLUMN($F$1),FALSE),"") -> 0 | M7: =IFERROR(VLOOKUP($C7,武器!$1:$998,COLUMN(AA$1),FALSE)*VLOOKUP($D7,素材!$1:$1016,COLUMN($G$1),FALSE),"") -> 0 | N7: =IFERROR(VLOOKUP($C7,武器!$1:$998,COLUMN(I$1),FALSE),"") -> 0 | O7: =IFERROR((VLOOKUP($C7,武器!$1:$998,COLUMN(K$1),FALSE)+VLOOKUP($D7,素材!$1:$1016,COLUMN(H$1),FALSE))*100+IFERROR(VLOOKUP($CI7,装強!$1:$999,COLUMN(O$1),FALSE),0),"") -> 10 | P7: =IFERROR((VLOOKUP($C7,武器!$1:$998,COLUMN(L$1),FALSE)+VLOOKUP($D7,素材!$1:$1016,COLUMN(I$1),FALSE))*100+IFERROR(VLOOKUP($CI7,装強!$1:$999,COLUMN(P$1),FALSE),0),"") -> 150 | Q7: =IFERROR(ROUNDUP(VLOOKUP($C7,武器!$1:$998,COLUMN(M$1),FALSE)*(VLOOKUP($D7,素材!$1:$1002,COLUMN(D$1),FALSE)/100),1),"") -> -2.5 | R7: =IFERROR(ROUNDUP(VLOOKUP($C7,武器!$1:$998,COLUMN(N$1),FALSE)*(VLOOKUP($D7,素材!$1:$1002,COLUMN(D$1),FALSE)/100),1),"") -> -2.5 | S7: =IFERROR(VLOOKUP($C7,武器!$1:$998,COLUMN(P$1),FALSE),"") -> 0 | T7: =IFERROR(VLOOKUP($C7,武器!$1:$998,COLUMN(Q$1),FALSE),"") -> 0 | U7: =IFERROR(VLOOKUP($C7,武器!$1:$998,COLUMN(R$1),FALSE),"") -> 0 | V7: =IFERROR(VLOOKUP($C7,武器!$1:$998,COLUMN(Q$1),FALSE),"") -> 0 | W7: =IFERROR(VLOOKUP($C7,武器!$1:$998,COLUMN(T$1),FALSE),"") -> A | Y7: =IFERROR(VLOOKUP($C7,武器!$1:$998,COLUMN(U$1),FALSE),"") -> 0 | Z7: =IFERROR(ROUNDUP(VLOOKUP($C7,武器!$1:$998,COLUMN(O$1),FALSE)*VLOOKUP($D7,素材!$1:$1016,COLUMN(E$1),FALSE),1),"") -> 0 | AA7: =IF(ISNUMBER(SEARCH(SUBSTITUTE(AA$1,RIGHT(AA$1,2),""),VLOOKUP($D7,素材!$1:$1016,COLUMN($F$1),FALSE))),VLOOKUP($C7,武器!$1:$998,COLUMN($O$1),FALSE)*VLOOKUP($D7,素材!$1:$1016,COLUMN($E$1),FALSE)/(LEN(VLOOKUP($D7,素材!$1:$1016,COLUMN($F$1),FALSE)) - LEN(SUBSTITUTE(VLOOKUP($D7,素材!$1:$1016,COLUMN($F$1),FALSE), "・", 0)) + 1), 0) -> 0 | AB7: =IF(ISNUMBER(SEARCH(SUBSTITUTE(AB$1,RIGHT(AB$1,2),""),VLOOKUP($D7,素材!$1:$1016,COLUMN($F$1),FALSE))),VLOOKUP($C7,武器!$1:$998,COLUMN($O$1),FALSE)*VLOOKUP($D7,素材!$1:$1016,COLUMN($E$1),FALSE)/(LEN(VLOOKUP($D7,素材!$1:$1016,COLUMN($F$1),FALSE)) - LEN(SUBSTITUTE(VLOOKUP($D7,素材!$1:$1016,COLUMN($F$1),FALSE), "・", 0)) + 1), 0) -> 0 | AC7: =IF(ISNUMBER(SEARCH(SUBSTITUTE(AC$1,RIGHT(AC$1,2),""),VLOOKUP($D7,素材!$1:$1016,COLUMN($F$1),FALSE))),VLOOKUP($C7,武器!$1:$998,COLUMN($O$1),FALSE)*VLOOKUP($D7,素材!$1:$1016,COLUMN($E$1),FALSE)/(LEN(VLOOKUP($D7,素材!$1:$1016,COLUMN($F$1),FALSE)) - LEN(SUBSTITUTE(VLOOKUP($D7,素材!$1:$1016,COLUMN($F$1),FALSE), "・", 0)) + 1), 0) -> 0 | AD7: =IF(ISNUMBER(SEARCH(SUBSTITUTE(AD$1,RIGHT(AD$1,2),""),VLOOKUP($D7,素材!$1:$1016,COLUMN($F$1),FALSE))),VLOOKUP($C7,武器!$1:$998,COLUMN($O$1),FALSE)*VLOOKUP($D7,素材!$1:$1016,COLUMN($E$1),FALSE)/(LEN(VLOOKUP($D7,素材!$1:$1016,COLUMN($F$1),FALSE)) - LEN(SUBSTITUTE(VLOOKUP($D7,素材!$1:$1016,COLUMN($F$1),FALSE), "・", 0)) + 1), 0) -> 0 | AE7: =IF(ISNUMBER(SEARCH(SUBSTITUTE(AE$1,RIGHT(AE$1,2),""),VLOOKUP($D7,素材!$1:$1016,COLUMN($F$1),FALSE))),VLOOKUP($C7,武器!$1:$998,COLUMN($O$1),FALSE)*VLOOKUP($D7,素材!$1:$1016,COLUMN($E$1),FALSE)/(LEN(VLOOKUP($D7,素材!$1:$1016,COLUMN($F$1),FALSE)) - LEN(SUBSTITUTE(VLOOKUP($D7,素材!$1:$1016,COLUMN($F$1),FALSE), "・", 0)) + 1), 0) -> 0 | AF7: =IF(ISNUMBER(SEARCH(SUBSTITUTE(AF$1,RIGHT(AF$1,2),""),VLOOKUP($D7,素材!$1:$1016,COLUMN($F$1),FALSE))),VLOOKUP($C7,武器!$1:$998,COLUMN($O$1),FALSE)*VLOOKUP($D7,素材!$1:$1016,COLUMN($E$1),FALSE)/(LEN(VLOOKUP($D7,素材!$1:$1016,COLUMN($F$1),FALSE)) - LEN(SUBSTITUTE(VLOOKUP($D7,素材!$1:$1016,COLUMN($F$1),FALSE), "・", 0)) + 1), 0) -> 0 | AG7: =IF(ISNUMBER(SEARCH(SUBSTITUTE(AG$1,RIGHT(AG$1,2),""),VLOOKUP($D7,素材!$1:$1016,COLUMN($F$1),FALSE))),VLOOKUP($C7,武器!$1:$998,COLUMN($O$1),FALSE)*VLOOKUP($D7,素材!$1:$1016,COLUMN($E$1),FALSE)/(LEN(VLOOKUP($D7,素材!$1:$1016,COLUMN($F$1),FALSE)) - LEN(SUBSTITUTE(VLOOKUP($D7,素材!$1:$1016,COLUMN($F$1),FALSE), "・", 0)) + 1), 0) -> 0 | AH7: =IF(ISNUMBER(SEARCH(SUBSTITUTE(AH$1,RIGHT(AH$1,2),""),VLOOKUP($D7,素材!$1:$1016,COLUMN($F$1),FALSE))),VLOOKUP($C7,武器!$1:$998,COLUMN($O$1),FALSE)*VLOOKUP($D7,素材!$1:$1016,COLUMN($E$1),FALSE)/(LEN(VLOOKUP($D7,素材!$1:$1016,COLUMN($F$1),FALSE)) - LEN(SUBSTITUTE(VLOOKUP($D7,素材!$1:$1016,COLUMN($F$1),FALSE), "・", 0)) + 1), 0) -> 0 | ... BE7: =IF(ISNUMBER(SEARCH(SUBSTITUTE(BE$1,RIGHT(BE$1,2),""),VLOOKUP($D7,素材!$1:$1016,COLUMN($F$1),FALSE))),VLOOKUP($C7,武器!$1:$998,COLUMN($O$1),FALSE)*VLOOKUP($D7,素材!$1:$1016,COLUMN($E$1),FALSE)/(LEN(VLOOKUP($D7,素材!$1:$1016,COLUMN($F$1),FALSE)) - LEN(SUBSTITUTE(VLOOKUP($D7,素材!$1:$1016,COLUMN($F$1),FALSE), "・", 0)) + 1), 0) -> 0 | CL7: =SUM(G7:I7) -> 27 | CM7: =IF(E7="武器",IF(J7-1>SUM(G7:I7),"盾",IF(MAX(G7:I7)=G7,"切断",IF(MAX(G7:I7)=H7,"貫通",IF(MAX(G7:I7)=I7,"打撃","射撃")))),E7)&".webp" -> 切断.webp | CN7: =IFERROR(VLOOKUP($C7,武器!$1:$998,COLUMN(V$1),FALSE)*VLOOKUP($D7,素材!$1:$1016,COLUMN(N$1),FALSE)+IF(CI7="",0,VLOOKUP($CI7,装強!$1:$1008,COLUMN($CK$1),FALSE)),"") -> 400 | CO7: =VLOOKUP(D7,素材!$A:$O,COLUMN(素材!O$1),FALSE) -> 一般的な鉄。量産品を作るのに使用されることが多い | CP7: =VLOOKUP(C7,武器!$A:$W,COLUMN(武器!W$1),FALSE) -> 長剣。長く重い分扱いにくいが威力が高い。 | CR7: ="e_"&ROW(CR7) -> e_7 | CS7: =CN7*100 -> 40000
A8: =D8&"の"&C8 -> 鉄の大剣 | B8: =IFERROR(VLOOKUP($D8,素材!$1:$1016,COLUMN($B$1),FALSE)&"・"&VLOOKUP($C8,武器!$1:$998,COLUMN(B$1),FALSE),"") -> アイアン・バスターソード | C8: 大剣 | D8: 鉄 | E8: =IFERROR(VLOOKUP(C8,武器!$1:$998,COLUMN(C$1),FALSE),"") -> 武器 | F8: =IFERROR(ROUNDDOWN((VLOOKUP($C8,武器!$1:$998,COLUMN(D$1),FALSE)+IFERROR(VLOOKUP($CI8,装強!$1:$999,COLUMN(F$1),FALSE),0))*VLOOKUP($D8,素材!$1:$1016,COLUMN(D$1),FALSE),0),"") -> 125 | G8: =IFERROR(ROUNDDOWN((VLOOKUP($C8,武器!$1:$998,COLUMN(E$1),FALSE)+IFERROR(VLOOKUP($CI8,装強!$1:$999,COLUMN(G$1),FALSE),0))*VLOOKUP($D8,素材!$1:$1016,COLUMN($E$1),FALSE),0),"") -> 18 | H8: =IFERROR(ROUNDDOWN((VLOOKUP($C8,武器!$1:$998,COLUMN(F$1),FALSE)+IFERROR(VLOOKUP($CI8,装強!$1:$999,COLUMN(H$1),FALSE),0))*VLOOKUP($D8,素材!$1:$1016,COLUMN($E$1),FALSE),0),"") -> 9 | I8: =IFERROR(ROUNDDOWN((VLOOKUP($C8,武器!$1:$998,COLUMN(G$1),FALSE)+IFERROR(VLOOKUP($CI8,装強!$1:$999,COLUMN(I$1),FALSE),0))*VLOOKUP($D8,素材!$1:$1016,COLUMN($E$1),FALSE),0),"") -> 4 | J8: =IFERROR(ROUNDDOWN((VLOOKUP($C8,武器!$1:$998,COLUMN(H$1),FALSE)+IFERROR(VLOOKUP($CI8,装強!$1:$999,COLUMN(J$1),FALSE),0))*VLOOKUP($D8,素材!$1:$1016,COLUMN($E$1),FALSE),0),"") -> 22 | K8: =IFERROR(ROUNDDOWN((VLOOKUP($C8,武器!$1:$998,COLUMN(I$1),FALSE)+IFERROR(VLOOKUP($CI8,装強!$1:$999,COLUMN(K$1),FALSE),0))*VLOOKUP($D8,素材!$1:$1016,COLUMN($E$1),FALSE),0),"") -> 0 | L8: =IFERROR(VLOOKUP($D8,素材!$1:$1016,COLUMN($F$1),FALSE),"") -> 0 | M8: =IFERROR(VLOOKUP($C8,武器!$1:$998,COLUMN(AA$1),FALSE)*VLOOKUP($D8,素材!$1:$1016,COLUMN($G$1),FALSE),"") -> 0 | N8: =IFERROR(VLOOKUP($C8,武器!$1:$998,COLUMN(I$1),FALSE),"") -> 0 | O8: =IFERROR((VLOOKUP($C8,武器!$1:$998,COLUMN(K$1),FALSE)+VLOOKUP($D8,素材!$1:$1016,COLUMN(H$1),FALSE))*100+IFERROR(VLOOKUP($CI8,装強!$1:$999,COLUMN(O$1),FALSE),0),"") -> 10 | P8: =IFERROR((VLOOKUP($C8,武器!$1:$998,COLUMN(L$1),FALSE)+VLOOKUP($D8,素材!$1:$1016,COLUMN(I$1),FALSE))*100+IFERROR(VLOOKUP($CI8,装強!$1:$999,COLUMN(P$1),FALSE),0),"") -> 150 | Q8: =IFERROR(ROUNDUP(VLOOKUP($C8,武器!$1:$998,COLUMN(M$1),FALSE)*(VLOOKUP($D8,素材!$1:$1002,COLUMN(D$1),FALSE)/100),1),"") -> -7.5 | R8: =IFERROR(ROUNDUP(VLOOKUP($C8,武器!$1:$998,COLUMN(N$1),FALSE)*(VLOOKUP($D8,素材!$1:$1002,COLUMN(D$1),FALSE)/100),1),"") -> -7.5 | S8: =IFERROR(VLOOKUP($C8,武器!$1:$998,COLUMN(P$1),FALSE),"") -> 0 | T8: =IFERROR(VLOOKUP($C8,武器!$1:$998,COLUMN(Q$1),FALSE),"") -> 0 | U8: =IFERROR(VLOOKUP($C8,武器!$1:$998,COLUMN(R$1),FALSE),"") -> 0 | V8: =IFERROR(VLOOKUP($C8,武器!$1:$998,COLUMN(Q$1),FALSE),"") -> 0 | W8: =IFERROR(VLOOKUP($C8,武器!$1:$998,COLUMN(T$1),FALSE),"") -> A | Y8: =IFERROR(VLOOKUP($C8,武器!$1:$998,COLUMN(U$1),FALSE),"") -> 0 | Z8: =IFERROR(ROUNDUP(VLOOKUP($C8,武器!$1:$998,COLUMN(O$1),FALSE)*VLOOKUP($D8,素材!$1:$1016,COLUMN(E$1),FALSE),1),"") -> 0 | AA8: =IF(ISNUMBER(SEARCH(SUBSTITUTE(AA$1,RIGHT(AA$1,2),""),VLOOKUP($D8,素材!$1:$1016,COLUMN($F$1),FALSE))),VLOOKUP($C8,武器!$1:$998,COLUMN($O$1),FALSE)*VLOOKUP($D8,素材!$1:$1016,COLUMN($E$1),FALSE)/(LEN(VLOOKUP($D8,素材!$1:$1016,COLUMN($F$1),FALSE)) - LEN(SUBSTITUTE(VLOOKUP($D8,素材!$1:$1016,COLUMN($F$1),FALSE), "・", 0)) + 1), 0) -> 0 | AB8: =IF(ISNUMBER(SEARCH(SUBSTITUTE(AB$1,RIGHT(AB$1,2),""),VLOOKUP($D8,素材!$1:$1016,COLUMN($F$1),FALSE))),VLOOKUP($C8,武器!$1:$998,COLUMN($O$1),FALSE)*VLOOKUP($D8,素材!$1:$1016,COLUMN($E$1),FALSE)/(LEN(VLOOKUP($D8,素材!$1:$1016,COLUMN($F$1),FALSE)) - LEN(SUBSTITUTE(VLOOKUP($D8,素材!$1:$1016,COLUMN($F$1),FALSE), "・", 0)) + 1), 0) -> 0 | AC8: =IF(ISNUMBER(SEARCH(SUBSTITUTE(AC$1,RIGHT(AC$1,2),""),VLOOKUP($D8,素材!$1:$1016,COLUMN($F$1),FALSE))),VLOOKUP($C8,武器!$1:$998,COLUMN($O$1),FALSE)*VLOOKUP($D8,素材!$1:$1016,COLUMN($E$1),FALSE)/(LEN(VLOOKUP($D8,素材!$1:$1016,COLUMN($F$1),FALSE)) - LEN(SUBSTITUTE(VLOOKUP($D8,素材!$1:$1016,COLUMN($F$1),FALSE), "・", 0)) + 1), 0) -> 0 | AD8: =IF(ISNUMBER(SEARCH(SUBSTITUTE(AD$1,RIGHT(AD$1,2),""),VLOOKUP($D8,素材!$1:$1016,COLUMN($F$1),FALSE))),VLOOKUP($C8,武器!$1:$998,COLUMN($O$1),FALSE)*VLOOKUP($D8,素材!$1:$1016,COLUMN($E$1),FALSE)/(LEN(VLOOKUP($D8,素材!$1:$1016,COLUMN($F$1),FALSE)) - LEN(SUBSTITUTE(VLOOKUP($D8,素材!$1:$1016,COLUMN($F$1),FALSE), "・", 0)) + 1), 0) -> 0 | AE8: =IF(ISNUMBER(SEARCH(SUBSTITUTE(AE$1,RIGHT(AE$1,2),""),VLOOKUP($D8,素材!$1:$1016,COLUMN($F$1),FALSE))),VLOOKUP($C8,武器!$1:$998,COLUMN($O$1),FALSE)*VLOOKUP($D8,素材!$1:$1016,COLUMN($E$1),FALSE)/(LEN(VLOOKUP($D8,素材!$1:$1016,COLUMN($F$1),FALSE)) - LEN(SUBSTITUTE(VLOOKUP($D8,素材!$1:$1016,COLUMN($F$1),FALSE), "・", 0)) + 1), 0) -> 0 | AF8: =IF(ISNUMBER(SEARCH(SUBSTITUTE(AF$1,RIGHT(AF$1,2),""),VLOOKUP($D8,素材!$1:$1016,COLUMN($F$1),FALSE))),VLOOKUP($C8,武器!$1:$998,COLUMN($O$1),FALSE)*VLOOKUP($D8,素材!$1:$1016,COLUMN($E$1),FALSE)/(LEN(VLOOKUP($D8,素材!$1:$1016,COLUMN($F$1),FALSE)) - LEN(SUBSTITUTE(VLOOKUP($D8,素材!$1:$1016,COLUMN($F$1),FALSE), "・", 0)) + 1), 0) -> 0 | AG8: =IF(ISNUMBER(SEARCH(SUBSTITUTE(AG$1,RIGHT(AG$1,2),""),VLOOKUP($D8,素材!$1:$1016,COLUMN($F$1),FALSE))),VLOOKUP($C8,武器!$1:$998,COLUMN($O$1),FALSE)*VLOOKUP($D8,素材!$1:$1016,COLUMN($E$1),FALSE)/(LEN(VLOOKUP($D8,素材!$1:$1016,COLUMN($F$1),FALSE)) - LEN(SUBSTITUTE(VLOOKUP($D8,素材!$1:$1016,COLUMN($F$1),FALSE), "・", 0)) + 1), 0) -> 0 | AH8: =IF(ISNUMBER(SEARCH(SUBSTITUTE(AH$1,RIGHT(AH$1,2),""),VLOOKUP($D8,素材!$1:$1016,COLUMN($F$1),FALSE))),VLOOKUP($C8,武器!$1:$998,COLUMN($O$1),FALSE)*VLOOKUP($D8,素材!$1:$1016,COLUMN($E$1),FALSE)/(LEN(VLOOKUP($D8,素材!$1:$1016,COLUMN($F$1),FALSE)) - LEN(SUBSTITUTE(VLOOKUP($D8,素材!$1:$1016,COLUMN($F$1),FALSE), "・", 0)) + 1), 0) -> 0 | ... BE8: =IF(ISNUMBER(SEARCH(SUBSTITUTE(BE$1,RIGHT(BE$1,2),""),VLOOKUP($D8,素材!$1:$1016,COLUMN($F$1),FALSE))),VLOOKUP($C8,武器!$1:$998,COLUMN($O$1),FALSE)*VLOOKUP($D8,素材!$1:$1016,COLUMN($E$1),FALSE)/(LEN(VLOOKUP($D8,素材!$1:$1016,COLUMN($F$1),FALSE)) - LEN(SUBSTITUTE(VLOOKUP($D8,素材!$1:$1016,COLUMN($F$1),FALSE), "・", 0)) + 1), 0) -> 0 | CL8: =SUM(G8:I8) -> 31 | CM8: =IF(E8="武器",IF(J8-1>SUM(G8:I8),"盾",IF(MAX(G8:I8)=G8,"切断",IF(MAX(G8:I8)=H8,"貫通",IF(MAX(G8:I8)=I8,"打撃","射撃")))),E8)&".webp" -> 切断.webp | CN8: =IFERROR(VLOOKUP($C8,武器!$1:$998,COLUMN(V$1),FALSE)*VLOOKUP($D8,素材!$1:$1016,COLUMN(N$1),FALSE)+IF(CI8="",0,VLOOKUP($CI8,装強!$1:$1008,COLUMN($CK$1),FALSE)),"") -> 600 | CO8: =VLOOKUP(D8,素材!$A:$O,COLUMN(素材!O$1),FALSE) -> 一般的な鉄。量産品を作るのに使用されることが多い | CP8: =VLOOKUP(C8,武器!$A:$W,COLUMN(武器!W$1),FALSE) -> 大剣。非常に重いが威力が突出して高い武器。大きい分ガードにも向いている | CR8: ="e_"&ROW(CR8) -> e_8 | CS8: =CN8*100 -> 60000
A9: =D9&"の"&C9 -> 鉄の細剣 | B9: =IFERROR(VLOOKUP($D9,素材!$1:$1016,COLUMN($B$1),FALSE)&"・"&VLOOKUP($C9,武器!$1:$998,COLUMN(B$1),FALSE),"") -> アイアン・レイピア | C9: 細剣 | D9: 鉄 | E9: =IFERROR(VLOOKUP(C9,武器!$1:$998,COLUMN(C$1),FALSE),"") -> 武器 | F9: =IFERROR(ROUNDDOWN((VLOOKUP($C9,武器!$1:$998,COLUMN(D$1),FALSE)+IFERROR(VLOOKUP($CI9,装強!$1:$999,COLUMN(F$1),FALSE),0))*VLOOKUP($D9,素材!$1:$1016,COLUMN(D$1),FALSE),0),"") -> 100 | G9: =IFERROR(ROUNDDOWN((VLOOKUP($C9,武器!$1:$998,COLUMN(E$1),FALSE)+IFERROR(VLOOKUP($CI9,装強!$1:$999,COLUMN(G$1),FALSE),0))*VLOOKUP($D9,素材!$1:$1016,COLUMN($E$1),FALSE),0),"") -> 9 | H9: =IFERROR(ROUNDDOWN((VLOOKUP($C9,武器!$1:$998,COLUMN(F$1),FALSE)+IFERROR(VLOOKUP($CI9,装強!$1:$999,COLUMN(H$1),FALSE),0))*VLOOKUP($D9,素材!$1:$1016,COLUMN($E$1),FALSE),0),"") -> 13 | I9: =IFERROR(ROUNDDOWN((VLOOKUP($C9,武器!$1:$998,COLUMN(G$1),FALSE)+IFERROR(VLOOKUP($CI9,装強!$1:$999,COLUMN(I$1),FALSE),0))*VLOOKUP($D9,素材!$1:$1016,COLUMN($E$1),FALSE),0),"") -> 0 | J9: =IFERROR(ROUNDDOWN((VLOOKUP($C9,武器!$1:$998,COLUMN(H$1),FALSE)+IFERROR(VLOOKUP($CI9,装強!$1:$999,COLUMN(J$1),FALSE),0))*VLOOKUP($D9,素材!$1:$1016,COLUMN($E$1),FALSE),0),"") -> 16 | K9: =IFERROR(ROUNDDOWN((VLOOKUP($C9,武器!$1:$998,COLUMN(I$1),FALSE)+IFERROR(VLOOKUP($CI9,装強!$1:$999,COLUMN(K$1),FALSE),0))*VLOOKUP($D9,素材!$1:$1016,COLUMN($E$1),FALSE),0),"") -> 0 | L9: =IFERROR(VLOOKUP($D9,素材!$1:$1016,COLUMN($F$1),FALSE),"") -> 0 | M9: =IFERROR(VLOOKUP($C9,武器!$1:$998,COLUMN(AA$1),FALSE)*VLOOKUP($D9,素材!$1:$1016,COLUMN($G$1),FALSE),"") -> 0 | N9: =IFERROR(VLOOKUP($C9,武器!$1:$998,COLUMN(I$1),FALSE),"") -> 0 | O9: =IFERROR((VLOOKUP($C9,武器!$1:$998,COLUMN(K$1),FALSE)+VLOOKUP($D9,素材!$1:$1016,COLUMN(H$1),FALSE))*100+IFERROR(VLOOKUP($CI9,装強!$1:$999,COLUMN(O$1),FALSE),0),"") -> 15 | P9: =IFERROR((VLOOKUP($C9,武器!$1:$998,COLUMN(L$1),FALSE)+VLOOKUP($D9,素材!$1:$1016,COLUMN(I$1),FALSE))*100+IFERROR(VLOOKUP($CI9,装強!$1:$999,COLUMN(P$1),FALSE),0),"") -> 125 | Q9: =IFERROR(ROUNDUP(VLOOKUP($C9,武器!$1:$998,COLUMN(M$1),FALSE)*(VLOOKUP($D9,素材!$1:$1002,COLUMN(D$1),FALSE)/100),1),"") -> 0 | R9: =IFERROR(ROUNDUP(VLOOKUP($C9,武器!$1:$998,COLUMN(N$1),FALSE)*(VLOOKUP($D9,素材!$1:$1002,COLUMN(D$1),FALSE)/100),1),"") -> 0 | S9: =IFERROR(VLOOKUP($C9,武器!$1:$998,COLUMN(P$1),FALSE),"") -> 0 | T9: =IFERROR(VLOOKUP($C9,武器!$1:$998,COLUMN(Q$1),FALSE),"") -> 0 | U9: =IFERROR(VLOOKUP($C9,武器!$1:$998,COLUMN(R$1),FALSE),"") -> 0 | V9: =IFERROR(VLOOKUP($C9,武器!$1:$998,COLUMN(Q$1),FALSE),"") -> 0 | W9: =IFERROR(VLOOKUP($C9,武器!$1:$998,COLUMN(T$1),FALSE),"") -> A | Y9: =IFERROR(VLOOKUP($C9,武器!$1:$998,COLUMN(U$1),FALSE),"") -> 片手適正Ⅰ | Z9: =IFERROR(ROUNDUP(VLOOKUP($C9,武器!$1:$998,COLUMN(O$1),FALSE)*VLOOKUP($D9,素材!$1:$1016,COLUMN(E$1),FALSE),1),"") -> 0 | AA9: =IF(ISNUMBER(SEARCH(SUBSTITUTE(AA$1,RIGHT(AA$1,2),""),VLOOKUP($D9,素材!$1:$1016,COLUMN($F$1),FALSE))),VLOOKUP($C9,武器!$1:$998,COLUMN($O$1),FALSE)*VLOOKUP($D9,素材!$1:$1016,COLUMN($E$1),FALSE)/(LEN(VLOOKUP($D9,素材!$1:$1016,COLUMN($F$1),FALSE)) - LEN(SUBSTITUTE(VLOOKUP($D9,素材!$1:$1016,COLUMN($F$1),FALSE), "・", 0)) + 1), 0) -> 0 | AB9: =IF(ISNUMBER(SEARCH(SUBSTITUTE(AB$1,RIGHT(AB$1,2),""),VLOOKUP($D9,素材!$1:$1016,COLUMN($F$1),FALSE))),VLOOKUP($C9,武器!$1:$998,COLUMN($O$1),FALSE)*VLOOKUP($D9,素材!$1:$1016,COLUMN($E$1),FALSE)/(LEN(VLOOKUP($D9,素材!$1:$1016,COLUMN($F$1),FALSE)) - LEN(SUBSTITUTE(VLOOKUP($D9,素材!$1:$1016,COLUMN($F$1),FALSE), "・", 0)) + 1), 0) -> 0 | AC9: =IF(ISNUMBER(SEARCH(SUBSTITUTE(AC$1,RIGHT(AC$1,2),""),VLOOKUP($D9,素材!$1:$1016,COLUMN($F$1),FALSE))),VLOOKUP($C9,武器!$1:$998,COLUMN($O$1),FALSE)*VLOOKUP($D9,素材!$1:$1016,COLUMN($E$1),FALSE)/(LEN(VLOOKUP($D9,素材!$1:$1016,COLUMN($F$1),FALSE)) - LEN(SUBSTITUTE(VLOOKUP($D9,素材!$1:$1016,COLUMN($F$1),FALSE), "・", 0)) + 1), 0) -> 0 | AD9: =IF(ISNUMBER(SEARCH(SUBSTITUTE(AD$1,RIGHT(AD$1,2),""),VLOOKUP($D9,素材!$1:$1016,COLUMN($F$1),FALSE))),VLOOKUP($C9,武器!$1:$998,COLUMN($O$1),FALSE)*VLOOKUP($D9,素材!$1:$1016,COLUMN($E$1),FALSE)/(LEN(VLOOKUP($D9,素材!$1:$1016,COLUMN($F$1),FALSE)) - LEN(SUBSTITUTE(VLOOKUP($D9,素材!$1:$1016,COLUMN($F$1),FALSE), "・", 0)) + 1), 0) -> 0 | AE9: =IF(ISNUMBER(SEARCH(SUBSTITUTE(AE$1,RIGHT(AE$1,2),""),VLOOKUP($D9,素材!$1:$1016,COLUMN($F$1),FALSE))),VLOOKUP($C9,武器!$1:$998,COLUMN($O$1),FALSE)*VLOOKUP($D9,素材!$1:$1016,COLUMN($E$1),FALSE)/(LEN(VLOOKUP($D9,素材!$1:$1016,COLUMN($F$1),FALSE)) - LEN(SUBSTITUTE(VLOOKUP($D9,素材!$1:$1016,COLUMN($F$1),FALSE), "・", 0)) + 1), 0) -> 0 | AF9: =IF(ISNUMBER(SEARCH(SUBSTITUTE(AF$1,RIGHT(AF$1,2),""),VLOOKUP($D9,素材!$1:$1016,COLUMN($F$1),FALSE))),VLOOKUP($C9,武器!$1:$998,COLUMN($O$1),FALSE)*VLOOKUP($D9,素材!$1:$1016,COLUMN($E$1),FALSE)/(LEN(VLOOKUP($D9,素材!$1:$1016,COLUMN($F$1),FALSE)) - LEN(SUBSTITUTE(VLOOKUP($D9,素材!$1:$1016,COLUMN($F$1),FALSE), "・", 0)) + 1), 0) -> 0 | AG9: =IF(ISNUMBER(SEARCH(SUBSTITUTE(AG$1,RIGHT(AG$1,2),""),VLOOKUP($D9,素材!$1:$1016,COLUMN($F$1),FALSE))),VLOOKUP($C9,武器!$1:$998,COLUMN($O$1),FALSE)*VLOOKUP($D9,素材!$1:$1016,COLUMN($E$1),FALSE)/(LEN(VLOOKUP($D9,素材!$1:$1016,COLUMN($F$1),FALSE)) - LEN(SUBSTITUTE(VLOOKUP($D9,素材!$1:$1016,COLUMN($F$1),FALSE), "・", 0)) + 1), 0) -> 0 | AH9: =IF(ISNUMBER(SEARCH(SUBSTITUTE(AH$1,RIGHT(AH$1,2),""),VLOOKUP($D9,素材!$1:$1016,COLUMN($F$1),FALSE))),VLOOKUP($C9,武器!$1:$998,COLUMN($O$1),FALSE)*VLOOKUP($D9,素材!$1:$1016,COLUMN($E$1),FALSE)/(LEN(VLOOKUP($D9,素材!$1:$1016,COLUMN($F$1),FALSE)) - LEN(SUBSTITUTE(VLOOKUP($D9,素材!$1:$1016,COLUMN($F$1),FALSE), "・", 0)) + 1), 0) -> 0 | ... BE9: =IF(ISNUMBER(SEARCH(SUBSTITUTE(BE$1,RIGHT(BE$1,2),""),VLOOKUP($D9,素材!$1:$1016,COLUMN($F$1),FALSE))),VLOOKUP($C9,武器!$1:$998,COLUMN($O$1),FALSE)*VLOOKUP($D9,素材!$1:$1016,COLUMN($E$1),FALSE)/(LEN(VLOOKUP($D9,素材!$1:$1016,COLUMN($F$1),FALSE)) - LEN(SUBSTITUTE(VLOOKUP($D9,素材!$1:$1016,COLUMN($F$1),FALSE), "・", 0)) + 1), 0) -> 0 | CL9: =SUM(G9:I9) -> 22 | CM9: =IF(E9="武器",IF(J9-1>SUM(G9:I9),"盾",IF(MAX(G9:I9)=G9,"切断",IF(MAX(G9:I9)=H9,"貫通",IF(MAX(G9:I9)=I9,"打撃","射撃")))),E9)&".webp" -> 貫通.webp | CN9: =IFERROR(VLOOKUP($C9,武器!$1:$998,COLUMN(V$1),FALSE)*VLOOKUP($D9,素材!$1:$1016,COLUMN(N$1),FALSE)+IF(CI9="",0,VLOOKUP($CI9,装強!$1:$1008,COLUMN($CK$1),FALSE)),"") -> 400 | CO9: =VLOOKUP(D9,素材!$A:$O,COLUMN(素材!O$1),FALSE) -> 一般的な鉄。量産品を作るのに使用されることが多い | CP9: =VLOOKUP(C9,武器!$A:$W,COLUMN(武器!W$1),FALSE) -> 細剣。刺突に優れた武器でCr率が高い | CR9: ="e_"&ROW(CR9) -> e_9 | CS9: =CN9*100 -> 40000
A10: =D10&"の"&C10 -> 鉄の刺剣 | B10: =IFERROR(VLOOKUP($D10,素材!$1:$1016,COLUMN($B$1),FALSE)&"・"&VLOOKUP($C10,武器!$1:$998,COLUMN(B$1),FALSE),"") -> アイアン・スティレット | C10: 刺剣 | D10: 鉄 | E10: =IFERROR(VLOOKUP(C10,武器!$1:$998,COLUMN(C$1),FALSE),"") -> 武器 | F10: =IFERROR(ROUNDDOWN((VLOOKUP($C10,武器!$1:$998,COLUMN(D$1),FALSE)+IFERROR(VLOOKUP($CI10,装強!$1:$999,COLUMN(F$1),FALSE),0))*VLOOKUP($D10,素材!$1:$1016,COLUMN(D$1),FALSE),0),"") -> 110 | G10: =IFERROR(ROUNDDOWN((VLOOKUP($C10,武器!$1:$998,COLUMN(E$1),FALSE)+IFERROR(VLOOKUP($CI10,装強!$1:$999,COLUMN(G$1),FALSE),0))*VLOOKUP($D10,素材!$1:$1016,COLUMN($E$1),FALSE),0),"") -> 4 | H10: =IFERROR(ROUNDDOWN((VLOOKUP($C10,武器!$1:$998,COLUMN(F$1),FALSE)+IFERROR(VLOOKUP($CI10,装強!$1:$999,COLUMN(H$1),FALSE),0))*VLOOKUP($D10,素材!$1:$1016,COLUMN($E$1),FALSE),0),"") -> 18 | I10: =IFERROR(ROUNDDOWN((VLOOKUP($C10,武器!$1:$998,COLUMN(G$1),FALSE)+IFERROR(VLOOKUP($CI10,装強!$1:$999,COLUMN(I$1),FALSE),0))*VLOOKUP($D10,素材!$1:$1016,COLUMN($E$1),FALSE),0),"") -> 0 | J10: =IFERROR(ROUNDDOWN((VLOOKUP($C10,武器!$1:$998,COLUMN(H$1),FALSE)+IFERROR(VLOOKUP($CI10,装強!$1:$999,COLUMN(J$1),FALSE),0))*VLOOKUP($D10,素材!$1:$1016,COLUMN($E$1),FALSE),0),"") -> 17 | K10: =IFERROR(ROUNDDOWN((VLOOKUP($C10,武器!$1:$998,COLUMN(I$1),FALSE)+IFERROR(VLOOKUP($CI10,装強!$1:$999,COLUMN(K$1),FALSE),0))*VLOOKUP($D10,素材!$1:$1016,COLUMN($E$1),FALSE),0),"") -> 0 | L10: =IFERROR(VLOOKUP($D10,素材!$1:$1016,COLUMN($F$1),FALSE),"") -> 0 | M10: =IFERROR(VLOOKUP($C10,武器!$1:$998,COLUMN(AA$1),FALSE)*VLOOKUP($D10,素材!$1:$1016,COLUMN($G$1),FALSE),"") -> 0 | N10: =IFERROR(VLOOKUP($C10,武器!$1:$998,COLUMN(I$1),FALSE),"") -> 0 | O10: =IFERROR((VLOOKUP($C10,武器!$1:$998,COLUMN(K$1),FALSE)+VLOOKUP($D10,素材!$1:$1016,COLUMN(H$1),FALSE))*100+IFERROR(VLOOKUP($CI10,装強!$1:$999,COLUMN(O$1),FALSE),0),"") -> 10 | P10: =IFERROR((VLOOKUP($C10,武器!$1:$998,COLUMN(L$1),FALSE)+VLOOKUP($D10,素材!$1:$1016,COLUMN(I$1),FALSE))*100+IFERROR(VLOOKUP($CI10,装強!$1:$999,COLUMN(P$1),FALSE),0),"") -> 150 | Q10: =IFERROR(ROUNDUP(VLOOKUP($C10,武器!$1:$998,COLUMN(M$1),FALSE)*(VLOOKUP($D10,素材!$1:$1002,COLUMN(D$1),FALSE)/100),1),"") -> 0 | R10: =IFERROR(ROUNDUP(VLOOKUP($C10,武器!$1:$998,COLUMN(N$1),FALSE)*(VLOOKUP($D10,素材!$1:$1002,COLUMN(D$1),FALSE)/100),1),"") -> 0 | S10: =IFERROR(VLOOKUP($C10,武器!$1:$998,COLUMN(P$1),FALSE),"") -> 0 | T10: =IFERROR(VLOOKUP($C10,武器!$1:$998,COLUMN(Q$1),FALSE),"") -> 0 | U10: =IFERROR(VLOOKUP($C10,武器!$1:$998,COLUMN(R$1),FALSE),"") -> 0 | V10: =IFERROR(VLOOKUP($C10,武器!$1:$998,COLUMN(Q$1),FALSE),"") -> 0 | W10: =IFERROR(VLOOKUP($C10,武器!$1:$998,COLUMN(T$1),FALSE),"") -> A | Y10: =IFERROR(VLOOKUP($C10,武器!$1:$998,COLUMN(U$1),FALSE),"") -> 片手適正Ⅰ | Z10: =IFERROR(ROUNDUP(VLOOKUP($C10,武器!$1:$998,COLUMN(O$1),FALSE)*VLOOKUP($D10,素材!$1:$1016,COLUMN(E$1),FALSE),1),"") -> 0 | AA10: =IF(ISNUMBER(SEARCH(SUBSTITUTE(AA$1,RIGHT(AA$1,2),""),VLOOKUP($D10,素材!$1:$1016,COLUMN($F$1),FALSE))),VLOOKUP($C10,武器!$1:$998,COLUMN($O$1),FALSE)*VLOOKUP($D10,素材!$1:$1016,COLUMN($E$1),FALSE)/(LEN(VLOOKUP($D10,素材!$1:$1016,COLUMN($F$1),FALSE)) - LEN(SUBSTITUTE(VLOOKUP($D10,素材!$1:$1016,COLUMN($F$1),FALSE), "・", 0)) + 1), 0) -> 0 | AB10: =IF(ISNUMBER(SEARCH(SUBSTITUTE(AB$1,RIGHT(AB$1,2),""),VLOOKUP($D10,素材!$1:$1016,COLUMN($F$1),FALSE))),VLOOKUP($C10,武器!$1:$998,COLUMN($O$1),FALSE)*VLOOKUP($D10,素材!$1:$1016,COLUMN($E$1),FALSE)/(LEN(VLOOKUP($D10,素材!$1:$1016,COLUMN($F$1),FALSE)) - LEN(SUBSTITUTE(VLOOKUP($D10,素材!$1:$1016,COLUMN($F$1),FALSE), "・", 0)) + 1), 0) -> 0 | AC10: =IF(ISNUMBER(SEARCH(SUBSTITUTE(AC$1,RIGHT(AC$1,2),""),VLOOKUP($D10,素材!$1:$1016,COLUMN($F$1),FALSE))),VLOOKUP($C10,武器!$1:$998,COLUMN($O$1),FALSE)*VLOOKUP($D10,素材!$1:$1016,COLUMN($E$1),FALSE)/(LEN(VLOOKUP($D10,素材!$1:$1016,COLUMN($F$1),FALSE)) - LEN(SUBSTITUTE(VLOOKUP($D10,素材!$1:$1016,COLUMN($F$1),FALSE), "・", 0)) + 1), 0) -> 0 | AD10: =IF(ISNUMBER(SEARCH(SUBSTITUTE(AD$1,RIGHT(AD$1,2),""),VLOOKUP($D10,素材!$1:$1016,COLUMN($F$1),FALSE))),VLOOKUP($C10,武器!$1:$998,COLUMN($O$1),FALSE)*VLOOKUP($D10,素材!$1:$1016,COLUMN($E$1),FALSE)/(LEN(VLOOKUP($D10,素材!$1:$1016,COLUMN($F$1),FALSE)) - LEN(SUBSTITUTE(VLOOKUP($D10,素材!$1:$1016,COLUMN($F$1),FALSE), "・", 0)) + 1), 0) -> 0 | AE10: =IF(ISNUMBER(SEARCH(SUBSTITUTE(AE$1,RIGHT(AE$1,2),""),VLOOKUP($D10,素材!$1:$1016,COLUMN($F$1),FALSE))),VLOOKUP($C10,武器!$1:$998,COLUMN($O$1),FALSE)*VLOOKUP($D10,素材!$1:$1016,COLUMN($E$1),FALSE)/(LEN(VLOOKUP($D10,素材!$1:$1016,COLUMN($F$1),FALSE)) - LEN(SUBSTITUTE(VLOOKUP($D10,素材!$1:$1016,COLUMN($F$1),FALSE), "・", 0)) + 1), 0) -> 0 | AF10: =IF(ISNUMBER(SEARCH(SUBSTITUTE(AF$1,RIGHT(AF$1,2),""),VLOOKUP($D10,素材!$1:$1016,COLUMN($F$1),FALSE))),VLOOKUP($C10,武器!$1:$998,COLUMN($O$1),FALSE)*VLOOKUP($D10,素材!$1:$1016,COLUMN($E$1),FALSE)/(LEN(VLOOKUP($D10,素材!$1:$1016,COLUMN($F$1),FALSE)) - LEN(SUBSTITUTE(VLOOKUP($D10,素材!$1:$1016,COLUMN($F$1),FALSE), "・", 0)) + 1), 0) -> 0 | AG10: =IF(ISNUMBER(SEARCH(SUBSTITUTE(AG$1,RIGHT(AG$1,2),""),VLOOKUP($D10,素材!$1:$1016,COLUMN($F$1),FALSE))),VLOOKUP($C10,武器!$1:$998,COLUMN($O$1),FALSE)*VLOOKUP($D10,素材!$1:$1016,COLUMN($E$1),FALSE)/(LEN(VLOOKUP($D10,素材!$1:$1016,COLUMN($F$1),FALSE)) - LEN(SUBSTITUTE(VLOOKUP($D10,素材!$1:$1016,COLUMN($F$1),FALSE), "・", 0)) + 1), 0) -> 0 | AH10: =IF(ISNUMBER(SEARCH(SUBSTITUTE(AH$1,RIGHT(AH$1,2),""),VLOOKUP($D10,素材!$1:$1016,COLUMN($F$1),FALSE))),VLOOKUP($C10,武器!$1:$998,COLUMN($O$1),FALSE)*VLOOKUP($D10,素材!$1:$1016,COLUMN($E$1),FALSE)/(LEN(VLOOKUP($D10,素材!$1:$1016,COLUMN($F$1),FALSE)) - LEN(SUBSTITUTE(VLOOKUP($D10,素材!$1:$1016,COLUMN($F$1),FALSE), "・", 0)) + 1), 0) -> 0 | ... BE10: =IF(ISNUMBER(SEARCH(SUBSTITUTE(BE$1,RIGHT(BE$1,2),""),VLOOKUP($D10,素材!$1:$1016,COLUMN($F$1),FALSE))),VLOOKUP($C10,武器!$1:$998,COLUMN($O$1),FALSE)*VLOOKUP($D10,素材!$1:$1016,COLUMN($E$1),FALSE)/(LEN(VLOOKUP($D10,素材!$1:$1016,COLUMN($F$1),FALSE)) - LEN(SUBSTITUTE(VLOOKUP($D10,素材!$1:$1016,COLUMN($F$1),FALSE), "・", 0)) + 1), 0) -> 0 | CL10: =SUM(G10:I10) -> 22 | CM10: =IF(E10="武器",IF(J10-1>SUM(G10:I10),"盾",IF(MAX(G10:I10)=G10,"切断",IF(MAX(G10:I10)=H10,"貫通",IF(MAX(G10:I10)=I10,"打撃","射撃")))),E10)&".webp" -> 貫通.webp | CN10: =IFERROR(VLOOKUP($C10,武器!$1:$998,COLUMN(V$1),FALSE)*VLOOKUP($D10,素材!$1:$1016,COLUMN(N$1),FALSE)+IF(CI10="",0,VLOOKUP($CI10,装強!$1:$1008,COLUMN($CK$1),FALSE)),"") -> 300 | CO10: =VLOOKUP(D10,素材!$A:$O,COLUMN(素材!O$1),FALSE) -> 一般的な鉄。量産品を作るのに使用されることが多い | CP10: =VLOOKUP(C10,武器!$A:$W,COLUMN(武器!W$1),FALSE) -> 刺剣。小型で精密な攻撃が可能な武器。 | CR10: ="e_"&ROW(CR10) -> e_10 | CS10: =CN10*100 -> 30000
A11: =D11&"の"&C11 -> 鉄の短槍 | B11: =IFERROR(VLOOKUP($D11,素材!$1:$1016,COLUMN($B$1),FALSE)&"・"&VLOOKUP($C11,武器!$1:$998,COLUMN(B$1),FALSE),"") -> アイアン・ショートスピア | C11: 短槍 | D11: 鉄 | E11: =IFERROR(VLOOKUP(C11,武器!$1:$998,COLUMN(C$1),FALSE),"") -> 武器 | F11: =IFERROR(ROUNDDOWN((VLOOKUP($C11,武器!$1:$998,COLUMN(D$1),FALSE)+IFERROR(VLOOKUP($CI11,装強!$1:$999,COLUMN(F$1),FALSE),0))*VLOOKUP($D11,素材!$1:$1016,COLUMN(D$1),FALSE),0),"") -> 105 | G11: =IFERROR(ROUNDDOWN((VLOOKUP($C11,武器!$1:$998,COLUMN(E$1),FALSE)+IFERROR(VLOOKUP($CI11,装強!$1:$999,COLUMN(G$1),FALSE),0))*VLOOKUP($D11,素材!$1:$1016,COLUMN($E$1),FALSE),0),"") -> 8 | H11: =IFERROR(ROUNDDOWN((VLOOKUP($C11,武器!$1:$998,COLUMN(F$1),FALSE)+IFERROR(VLOOKUP($CI11,装強!$1:$999,COLUMN(H$1),FALSE),0))*VLOOKUP($D11,素材!$1:$1016,COLUMN($E$1),FALSE),0),"") -> 14 | I11: =IFERROR(ROUNDDOWN((VLOOKUP($C11,武器!$1:$998,COLUMN(G$1),FALSE)+IFERROR(VLOOKUP($CI11,装強!$1:$999,COLUMN(I$1),FALSE),0))*VLOOKUP($D11,素材!$1:$1016,COLUMN($E$1),FALSE),0),"") -> 3 | J11: =IFERROR(ROUNDDOWN((VLOOKUP($C11,武器!$1:$998,COLUMN(H$1),FALSE)+IFERROR(VLOOKUP($CI11,装強!$1:$999,COLUMN(J$1),FALSE),0))*VLOOKUP($D11,素材!$1:$1016,COLUMN($E$1),FALSE),0),"") -> 17 | K11: =IFERROR(ROUNDDOWN((VLOOKUP($C11,武器!$1:$998,COLUMN(I$1),FALSE)+IFERROR(VLOOKUP($CI11,装強!$1:$999,COLUMN(K$1),FALSE),0))*VLOOKUP($D11,素材!$1:$1016,COLUMN($E$1),FALSE),0),"") -> 0 | L11: =IFERROR(VLOOKUP($D11,素材!$1:$1016,COLUMN($F$1),FALSE),"") -> 0 | M11: =IFERROR(VLOOKUP($C11,武器!$1:$998,COLUMN(AA$1),FALSE)*VLOOKUP($D11,素材!$1:$1016,COLUMN($G$1),FALSE),"") -> 0 | N11: =IFERROR(VLOOKUP($C11,武器!$1:$998,COLUMN(I$1),FALSE),"") -> 0 | O11: =IFERROR((VLOOKUP($C11,武器!$1:$998,COLUMN(K$1),FALSE)+VLOOKUP($D11,素材!$1:$1016,COLUMN(H$1),FALSE))*100+IFERROR(VLOOKUP($CI11,装強!$1:$999,COLUMN(O$1),FALSE),0),"") -> 10 | P11: =IFERROR((VLOOKUP($C11,武器!$1:$998,COLUMN(L$1),FALSE)+VLOOKUP($D11,素材!$1:$1016,COLUMN(I$1),FALSE))*100+IFERROR(VLOOKUP($CI11,装強!$1:$999,COLUMN(P$1),FALSE),0),"") -> 150 | Q11: =IFERROR(ROUNDUP(VLOOKUP($C11,武器!$1:$998,COLUMN(M$1),FALSE)*(VLOOKUP($D11,素材!$1:$1002,COLUMN(D$1),FALSE)/100),1),"") -> 0 | R11: =IFERROR(ROUNDUP(VLOOKUP($C11,武器!$1:$998,COLUMN(N$1),FALSE)*(VLOOKUP($D11,素材!$1:$1002,COLUMN(D$1),FALSE)/100),1),"") -> 0 | S11: =IFERROR(VLOOKUP($C11,武器!$1:$998,COLUMN(P$1),FALSE),"") -> 0 | T11: =IFERROR(VLOOKUP($C11,武器!$1:$998,COLUMN(Q$1),FALSE),"") -> 0 | U11: =IFERROR(VLOOKUP($C11,武器!$1:$998,COLUMN(R$1),FALSE),"") -> 0 | V11: =IFERROR(VLOOKUP($C11,武器!$1:$998,COLUMN(Q$1),FALSE),"") -> 0 | W11: =IFERROR(VLOOKUP($C11,武器!$1:$998,COLUMN(T$1),FALSE),"") -> A | Y11: =IFERROR(VLOOKUP($C11,武器!$1:$998,COLUMN(U$1),FALSE),"") -> 投擲強化 | Z11: =IFERROR(ROUNDUP(VLOOKUP($C11,武器!$1:$998,COLUMN(O$1),FALSE)*VLOOKUP($D11,素材!$1:$1016,COLUMN(E$1),FALSE),1),"") -> 0 | AA11: =IF(ISNUMBER(SEARCH(SUBSTITUTE(AA$1,RIGHT(AA$1,2),""),VLOOKUP($D11,素材!$1:$1016,COLUMN($F$1),FALSE))),VLOOKUP($C11,武器!$1:$998,COLUMN($O$1),FALSE)*VLOOKUP($D11,素材!$1:$1016,COLUMN($E$1),FALSE)/(LEN(VLOOKUP($D11,素材!$1:$1016,COLUMN($F$1),FALSE)) - LEN(SUBSTITUTE(VLOOKUP($D11,素材!$1:$1016,COLUMN($F$1),FALSE), "・", 0)) + 1), 0) -> 0 | AB11: =IF(ISNUMBER(SEARCH(SUBSTITUTE(AB$1,RIGHT(AB$1,2),""),VLOOKUP($D11,素材!$1:$1016,COLUMN($F$1),FALSE))),VLOOKUP($C11,武器!$1:$998,COLUMN($O$1),FALSE)*VLOOKUP($D11,素材!$1:$1016,COLUMN($E$1),FALSE)/(LEN(VLOOKUP($D11,素材!$1:$1016,COLUMN($F$1),FALSE)) - LEN(SUBSTITUTE(VLOOKUP($D11,素材!$1:$1016,COLUMN($F$1),FALSE), "・", 0)) + 1), 0) -> 0 | AC11: =IF(ISNUMBER(SEARCH(SUBSTITUTE(AC$1,RIGHT(AC$1,2),""),VLOOKUP($D11,素材!$1:$1016,COLUMN($F$1),FALSE))),VLOOKUP($C11,武器!$1:$998,COLUMN($O$1),FALSE)*VLOOKUP($D11,素材!$1:$1016,COLUMN($E$1),FALSE)/(LEN(VLOOKUP($D11,素材!$1:$1016,COLUMN($F$1),FALSE)) - LEN(SUBSTITUTE(VLOOKUP($D11,素材!$1:$1016,COLUMN($F$1),FALSE), "・", 0)) + 1), 0) -> 0 | AD11: =IF(ISNUMBER(SEARCH(SUBSTITUTE(AD$1,RIGHT(AD$1,2),""),VLOOKUP($D11,素材!$1:$1016,COLUMN($F$1),FALSE))),VLOOKUP($C11,武器!$1:$998,COLUMN($O$1),FALSE)*VLOOKUP($D11,素材!$1:$1016,COLUMN($E$1),FALSE)/(LEN(VLOOKUP($D11,素材!$1:$1016,COLUMN($F$1),FALSE)) - LEN(SUBSTITUTE(VLOOKUP($D11,素材!$1:$1016,COLUMN($F$1),FALSE), "・", 0)) + 1), 0) -> 0 | AE11: =IF(ISNUMBER(SEARCH(SUBSTITUTE(AE$1,RIGHT(AE$1,2),""),VLOOKUP($D11,素材!$1:$1016,COLUMN($F$1),FALSE))),VLOOKUP($C11,武器!$1:$998,COLUMN($O$1),FALSE)*VLOOKUP($D11,素材!$1:$1016,COLUMN($E$1),FALSE)/(LEN(VLOOKUP($D11,素材!$1:$1016,COLUMN($F$1),FALSE)) - LEN(SUBSTITUTE(VLOOKUP($D11,素材!$1:$1016,COLUMN($F$1),FALSE), "・", 0)) + 1), 0) -> 0 | AF11: =IF(ISNUMBER(SEARCH(SUBSTITUTE(AF$1,RIGHT(AF$1,2),""),VLOOKUP($D11,素材!$1:$1016,COLUMN($F$1),FALSE))),VLOOKUP($C11,武器!$1:$998,COLUMN($O$1),FALSE)*VLOOKUP($D11,素材!$1:$1016,COLUMN($E$1),FALSE)/(LEN(VLOOKUP($D11,素材!$1:$1016,COLUMN($F$1),FALSE)) - LEN(SUBSTITUTE(VLOOKUP($D11,素材!$1:$1016,COLUMN($F$1),FALSE), "・", 0)) + 1), 0) -> 0 | AG11: =IF(ISNUMBER(SEARCH(SUBSTITUTE(AG$1,RIGHT(AG$1,2),""),VLOOKUP($D11,素材!$1:$1016,COLUMN($F$1),FALSE))),VLOOKUP($C11,武器!$1:$998,COLUMN($O$1),FALSE)*VLOOKUP($D11,素材!$1:$1016,COLUMN($E$1),FALSE)/(LEN(VLOOKUP($D11,素材!$1:$1016,COLUMN($F$1),FALSE)) - LEN(SUBSTITUTE(VLOOKUP($D11,素材!$1:$1016,COLUMN($F$1),FALSE), "・", 0)) + 1), 0) -> 0 | AH11: =IF(ISNUMBER(SEARCH(SUBSTITUTE(AH$1,RIGHT(AH$1,2),""),VLOOKUP($D11,素材!$1:$1016,COLUMN($F$1),FALSE))),VLOOKUP($C11,武器!$1:$998,COLUMN($O$1),FALSE)*VLOOKUP($D11,素材!$1:$1016,COLUMN($E$1),FALSE)/(LEN(VLOOKUP($D11,素材!$1:$1016,COLUMN($F$1),FALSE)) - LEN(SUBSTITUTE(VLOOKUP($D11,素材!$1:$1016,COLUMN($F$1),FALSE), "・", 0)) + 1), 0) -> 0 | ... BE11: =IF(ISNUMBER(SEARCH(SUBSTITUTE(BE$1,RIGHT(BE$1,2),""),VLOOKUP($D11,素材!$1:$1016,COLUMN($F$1),FALSE))),VLOOKUP($C11,武器!$1:$998,COLUMN($O$1),FALSE)*VLOOKUP($D11,素材!$1:$1016,COLUMN($E$1),FALSE)/(LEN(VLOOKUP($D11,素材!$1:$1016,COLUMN($F$1),FALSE)) - LEN(SUBSTITUTE(VLOOKUP($D11,素材!$1:$1016,COLUMN($F$1),FALSE), "・", 0)) + 1), 0) -> 0 | CL11: =SUM(G11:I11) -> 25 | CM11: =IF(E11="武器",IF(J11-1>SUM(G11:I11),"盾",IF(MAX(G11:I11)=G11,"切断",IF(MAX(G11:I11)=H11,"貫通",IF(MAX(G11:I11)=I11,"打撃","射撃")))),E11)&".webp" -> 貫通.webp | CN11: =IFERROR(VLOOKUP($C11,武器!$1:$998,COLUMN(V$1),FALSE)*VLOOKUP($D11,素材!$1:$1016,COLUMN(N$1),FALSE)+IF(CI11="",0,VLOOKUP($CI11,装強!$1:$1008,COLUMN($CK$1),FALSE)),"") -> 300 | CO11: =VLOOKUP(D11,素材!$A:$O,COLUMN(素材!O$1),FALSE) -> 一般的な鉄。量産品を作るのに使用されることが多い | CP11: =VLOOKUP(C11,武器!$A:$W,COLUMN(武器!W$1),FALSE) -> 短槍。短く扱いやすい槍で、投擲にも対応。 | CR11: ="e_"&ROW(CR11) -> e_11 | CS11: =CN11*100 -> 30000
